Workbook
Name f: #REF!
Name f: #REF!
Name f: #REF!

Sheet 비품현황표(전체)
A1: 약품코드 | B1: 일반명 | C1: 영문상품명 | D1: 규격 | E1: 보관조건 | F1: 기타 주의 사항 | G1: 42W | H1: 61W | I1: 62W | J1: 71W | K1: 72W | L1: 81W | M1: 82W | N1: 91W | O1: 92W | P1: 101W | Q1: 102W | R1: 111W | S1: 112W | T1: 121W | U1: SICU | V1: MICU | W1: AN | X1: DRL | Y1: OR | Z1: NICU | AA1: AER | AB1: 신속대응팀 | AC1: HBEF심혈관조영실 | AD1: ADR | AE1: DSR | AF1: PED | AG1: 체외순환실 | AH1: 외래주사실 | AI1: 영상의학과 | AJ1: 안과 | AK1: 재활의학과 | AL1: 산부인과 | AM1: 난임클리닉 | AN1: 이비인후과 | AO1: 피부과 | AP1: 소화기병검사실 | AQ1: 정형외과 | AR1: 신경과 | AS1: 비뇨기과 | AT1: 합계
A2: XXARIPIP3 | B2: Aripiprazole 300mg inj | C2: Abilify maintena 300mg inj | D2: 1SRG/BOX | E2: 차광 밀봉용기, 실온보관(1~30℃) | AH2: 3 | AT2: =SUM(G2:AS2) -> 3
A3: XXARIPIP4 | B3: Aripiprazole 400mg inj | C3: ABILIFY maintena 400MG inj | D3: 1SRG/BOX | E3: 차광 밀봉용기, 실온보관(1~30℃) | AH3: 3 | AT3: =SUM(G3:AS3) -> 3
A4: XXARPIP72 | C4: Abilify asimtufii 720mg inj | E4: 밀봉용기, 실온보관(1~30℃) | AH4: 3 | AT4: =SUM(G4:AS4) -> 3
A5: XXARPIP96 | C5: Abilify asimtufii 960mg inj | E5: 밀봉용기, 실온보관(1~30℃) | AH5: 3 | AT5: =SUM(G5:AS5) -> 3
A6: XAPH1 | B6: Acetaminophen 1g/100ml | C6: Acetphen 1g/100ml premix inj | D6: 1bag | E6: 실온보관(1~30℃), 밀봉용기 | G6: 2 | H6: 1 | K6: 1 | L6: 2 | M6: 2 | N6: 3 | O6: 2 | Q6: 3 | R6: 1 | U6: 3 | V6: 3 | W6: 50 | AA6: 5 | AD6: 1 | AE6: 2 | AT6: =SUM(G6:AS6) -> 81
A7: XTPA20 | B7: RH-tissue-type plasminogen activator | C7: Actylase 20mg/20ml inj | D7: 1VIAL/BOX | E7: 밀봉용기, 실온(1-30℃) 보관, 빛을 피하여 보관 | AA7: 3 | AT7: =SUM(G7:AS7) -> 3
A8: XTPA50 | B8: RH-tissue-type plasminogen activator | C8: Actylase 50mg/50ml inj | D8: 1VIAL/BOX | E8: 밀봉용기, 실온(1-30℃) 보관, 빛을 피하여 보관 | AA8: 1 | AT8: =SUM(G8:AS8) -> 1
A9: XNEFOP20 | B9: nefopam hydrochloride 20㎎/2㎖ | C9: Acupan 20mg/2mL inj | D9: 20AMP/BOX | E9: 밀봉용기, 실온(1～30℃)보관 | W9: 30 | AT9: =SUM(G9:AS9) -> 30
A10: XXTDAP5W | C10: Adacel 0.5ml PFS | E10: 동결을 피하여 2∼8℃에서 보관 | AF10: 5 | AH10: 5 | AT10: =SUM(G10:AS10) -> 10
A11: XADENO6 | B11: Adenosine 6mg | C11: Adenocor 6mg/2ml inj | D11: 6VIAL/BOX | E11: 밀봉용기 | V11: 5 | W11: 4 | AC11: 3 | AT11: =SUM(G11:AS11) -> 12
A12: X20AL1S | B12: Albumin 20% 100ml(SK) | C12: Albumin(SK) 20% 100ml inj | E12: 밀봉용기, 30℃이하에서 동결을 피하여 보관 | F12: 용량고주의 | W12: 2
A13: XPALON75 | B13: Palonosetron 0.075mg/1.5ml | C13: Aloxi 0.075mg/1.5ml inj | D13: 5vial/BOX | E13: 실온(1∼30℃)보관, 밀봉용기, 빛을 피하여 보관 | F13: 용량고주의 | I13: 1 | N13: 2 | W13: 20 | AT13: =SUM(G13:AS13) -> 23
A14: XPALON | B14: Palonsetron 0.05mg/ml | C14: Aloxi 0.25mg/5ml Inj | D14: 1VIAL/BOX | E14: 실온(1∼30℃)보관, 밀봉용기, 빛을 피하여 보관 | F14: 용량고주의 | AH14: 3 | AT14: =SUM(G14:AS14) -> 3
A15: XAMBR15 | B15: Ambroxol 15mg | C15: Ambroxol 15mg inj | D15: 50AMP/BOX | E15: 차광밀봉용기, 실온(1~30℃)보관 | F15: 유사모양 | I15: 2 | AT15: =SUM(G15:AS15) -> 2
A16: XC500 | B16: Ascorbic acid 500mg/2ml inj | C16: Ascorbic acid 500mg/2ml inj | D16: 50AMP/BOX | E16: 차광밀봉용기,실온(1~30℃)보관 | F16: 유사모양 | AH16: 6 | AT16: =SUM(G16:AS16) -> 6
A17: ASP1PR | B17: Aspirin enteric coated 100mg tab | C17: Aspirin protect 100mg tab | D17: 1500TAB/BOX | E17: 기밀용기, 실온(25℃이하)보관 | H17: 3 | P17: 3 | AA17: 3 | AC17: 6 | AT17: =SUM(G17:AS17) -> 15
A18: XATRO | B18: Atropine sulfate 0.5mg | C18: Atropine sulfate 0.5mg/1ml inj | D18: 50AMP/BOX | E18: 차광밀봉용기, 실온(1-30℃)보관 | W18: 44 | AC18: 10 | AT18: =SUM(G18:AS18) -> 54
A19: IPRAT-RS | B19: Ipratropium bromide inh.soln 500mcg/2ml | C19: Atrovent UDV 2ml/Amp | D19: 20AMP/BOX*54 | E19: 밀봉용기, 실온보관 | F19: 유사모양 | J19: 1 | P19: 3 | W19: 2 | AA19: 5 | AT19: =SUM(G19:AS19) -> 11
A20: XXHAV16W | B20: Hepatitis A vaccine 160U | C20: Avaxim 160u(adult) inj | D20: 1SRG/BOX | E20: 밀봉용기, 동결을 피하여 2∼8℃에서 차광보관 | AH20: 5 | AT20: =SUM(G20:AS20) -> 5
A21: XAMPSUL15 | B21: ampicillin sodium 1g, sulbactam sodium 0.5g | C21: Bactacin 1.5g inj | D21: 10vial/box | E21: 밀봉용기, 실온보관 | F21: 유사발음 | G21: 2 | AH21: 2 | AT21: =SUM(G21:AS21) -> 4
A22: BCG-H | B22: Freeze-dried glutamate BCG vac for percutaneous | C22: BCG vac.percutaneous 12mg/1.5ml | D22: 1amp | E22: 밀봉용기, 10℃이하 보관 | AF22: 2 | AT22: =SUM(G22:AS22) -> 2
A23: XBH | B23: Beecom hexa* | C23: Beecom hexa 2ml inj | D23: 50AMP/BOX | E23: 실온, 차광보관, 밀봉용기 | AH23: 2 | AT23: =SUM(G23:AS23) -> 2
A24: XXBROLU | B24: brolucizumab | C24: Beovu 19.8mg/0.165ml pfs | D24: 1srg/box | E24: 2~8℃ 보관, 얼리지 말 것, 차광보관 | AJ24: 1 | AT24: =SUM(G24:AS24) -> 1
A25: XBMETHA4W | B25: Betamethasone 4mg inj* | C25: Betamethasone 4mg inj | D25: 50AMP/BOX | E25: 차광밀봉용기, 실온(1~30℃)보관 | F25: 유사발음 | X25: 6 | AT25: =SUM(G25:AS25) -> 6
A26: XNICAR5 | B26: nicardipine hydrochloride | C26: Binicapin 5mg/5ml inj | D26: 25AMP/BOX | E26: 차광, 실온(1~30℃)보관 | G26: 3 | H26: 1 | I26: 2 | J26: 2 | K26: 1 | L26: 2 | M26: 2 | O26: 2 | P26: 2 | Q26: 2 | R26: 1 | S26: 2 | U26: 10 | V26: 2 | W26: 20 | AA26: 3 | AD26: 10 | AT26: =SUM(G26:AS26) -> 67
A27: XXHYAL20Y | C27: BM hyal 20mg pfs | E27: 밀봉용기, 실온(1~30℃)보관 | AP27: 3 | AQ27: 12 | AT27: =SUM(G27:AS27) -> 15
A28: XXHYAL40 | B28: Bonisenwons 40mg/2ml inj (sodium hyaluronate) | C28: Bonisenwons 40mg/2ml inj | D28: 1SRG/BOX | E28: 밀봉용기, 실온(1~30℃) 보관 | AT28: =SUM(G28:AS28) -> 0
A29: XCALCIT1 | B29: Calcitriol 1mcg | C29: Bonky 1mcg inj | D29: 10AMP/BOX | E29: 차광밀봉용기, 상온보관 | AD29: 20 | AT29: =SUM(G29:AS29) -> 20
A30: XIHEX3530 | C30: Bonorex 350 30ml inj | E30: 밀봉용기, 차광하여 실온(1～30℃)보관 | AQ30: 10 | AT30: =SUM(G30:AS30) -> 10
A31: XIBAND3W | B31: Ibandronate 3mg (PFS) | C31: Bonviva inj 3mg/3ml (PFS) | D31: 1SRG/BOX | E31: 밀봉용기, 실온(1-30℃)보관 | AH31: 3 | AT31: =SUM(G31:AS31) -> 3
A32: XEMOL1 | B32: Esmolol HCl 100mg | C32: Brevibloc 100mg inj | D32: 20VIA/BOX | E32: 실온보관 | U32: 2 | V32: 2 | W32: 20 | AA32: 2 | AT32: =SUM(G32:AS32) -> 26
A33: XEMOL25W | B33: Esmolol HCl 2.5g | C33: Brevibloc 2.5g inj(vial) | D33: 10VIAL/BOX | E33: 차광한 밀봉용기, 실온(1~30℃)보관 | AT33: =SUM(G33:AS33) -> 0
A34: TICAG90 | B34: Brilinta 90mg Tab (ticagrelor) | C34: Brilinta 90mg Tab | D34: 56TAB/BOX | E34: 기밀용기, 실온(1∼30℃)보관 | AA34: 2 | AC34: 4 | AT34: =SUM(G34:AS34) -> 6
A35: BSS-L | B35: BSS* | C35: BSS 500ml | D35: 500ML/BTL | E35: 2 ~ 25℃ 보관, 밀봉용기 | Y35: 10 | AT35: =SUM(G35:AS35) -> 10
A36: BSSP-L | B36: BSS plus* | C36: BSS plus 500ml | D36: 500ML/BTL | E36: 2℃ - 25℃ 보관, 밀봉용기 | Y36: 8 | AT36: =SUM(G36:AS36) -> 8
A37: BSS5-L | B37: BSS plastic bagtype 500ml | C37: BSS plastic bagtype 500ml | D37: 500ML/BAG | E37: 과열을 피하여 실온보관(8-27℃), 밀봉용기 | Y37: 12 | AT37: =SUM(G37:AS37) -> 12
A38: XIBUPR4P | B38: Bupensol 400mg/100ml inj (ibuprofen) | C38: Bupensol 400mg/100ml inj | D38: 100ML/BAG | E38: 밀봉용기, 실온(1~30℃)보관 | AA38: 5 | AT38: =SUM(G38:AS38) -> 5
A39: XBPCA5W | C39: Bupivacaine-HCl 0.5% 20ml inj HANA | E39: 차광밀봉용기, 실온(1~30℃)보관 | Y39: 30 | AT39: =SUM(G39:AS39) -> 30
A40: XXPCV21 | C40: Capvaxive 21 pfs | E40: 밀봉용기, 동결을 피하여 냉장(2~8℃) 보관, 차광 보관. | AH40: 2 | AT40: =SUM(G40:AS40) -> 2
...

Sheet Sheet1

Sheet Sheet4

Sheet Sheet3

Sheet 42
A1: no | B1: 약품코드 | C1: 일반명 | D1: 영문상품명 | E1: 규격 | F1: 보관조건 | G1: 혼돈주의약품 | H1: 24.05.16
A2: 1 | B2: XAPH1 | C2: Acetaminophen 1g/100ml | D2: Acetphen 1g/100ml premix inj | E2: 1bag | F2: 실온보관(1~30℃), 밀봉용기 | H2: 2
A3: 2 | B3: XAMPSUL15 | C3: ampicillin sodium 1g, sulbactam sodium 0.5g | D3: Bactacin 1.5g inj | E3: 10vial/box | F3: 밀봉용기, 실온보관 | G3: 유사발음 | H3: 2
A4: 3 | B4: XNICAR5 | D4: Binicapin 5mg/5ml inj | E4: 25amp/BOX | F4: 차광, 실온(1~30℃)보관 | H4: 3
A5: 4 | B5: XCMTAZ | C5: cefmetazole 1g inj | D5: Ceftacin 1g inj | E5: 11VIA/BOX | F5: 밀봉용기, 실온보관 | H5: 3
A6: 5 | B6: XPCMOL | C6: Propacetamol 1g | D6: Denogan 1g inj | E6: 10VIA/BOX | F6: 차광밀봉용기, 1~25℃보관 | H6: 6
A7: 6 | B7: XDXM | C7: Dexamethasone 5mg | D7: Dexamethasone 5mg inj | E7: 50AMP/BOX | F7: 차광한 밀봉용기, 실온(1 ~ 30℃) 보관 | G7: 유사발음 | H7: 2
A8: 7 | B8: XCZEDO2G | C8: Cefazedone 2g | D8: Fazidone 2g inj | E8: 10VIA/BOX | F8: 밀봉용기,실온(1~30℃)보관 | H8: 2
A9: 8 | B9: XFAMO2W | C9: Famotidine 20mg inj | D9: Gaster 20mg/10ml inj | E9: 10AMP/BOX*10 | F9: 밀봉용기, 실온보관(1~30℃) | H9: 3
A10: 9 | B10: XKROL | C10: Ketorolac tromethamine 30mg | D10: Keromin 30mg Inj | E10: 50AMP/BOX | F10: 차광밀봉용기, 실온(1-30℃)보관 | H10: 4
A11: 10 | B11: XLABETA20 | C11: Labetalol HCl 20mg inj | D11: Labesin 20mg/4ml inj | E11: 50AMP/BOX | F11: 차광밀봉용기, 실온보관 | H11: 3
A12: 11 | B12: XFURO | C12: Furosemide 20mg | D12: Lasix 20mg inj | E12: 50AMP/BOX | F12: 밀봉용기 실온보관 차광. | G12: 유사모양 | H12: 3
A13: 12 | B13: XMEXO | C13: Metoclopramide | D13: Macperan 10mg inj | E13: 50AMP/BOX | F13: 밀봉용기, 차광, 실온(1~30℃)보관 | H13: 4
A14: 13 | B14: XCPENIR | C14: Chlorpheniramine | D14: Peniramin 4mg/2ml inj | E14: 100AMP/BOX | F14: 밀봉용기 | H14: 2
A15: 14 | B15: XTAZOC4W | C15: Piperacillin sod 4g/Tazobactam 0.5g | D15: Tazoractam 4.5g inj | E15: 10VIAL/BOX | F15: 밀봉용기, 실온(1-30℃) 보관 | H15: 2
A16: 15 | B16: XTRAM50 | C16: Tramadol 50mg/ml | D16: Tridol 50mg inj | E16: 50AMP/BOX | F16: 밀봉용기, 실온(1～30℃)보관 | H16: 6
D17: 보유비품약 품목수 | H17: 15

Sheet 61
A1: NO | B1: 약품코드 | C1: 일반명 | D1: 영문상품명 | E1: 규격 | F1: 보관조건 | G1: 혼돈주의약품 | H1: 26.04.22
A2: 1 | B2: XAPH1 | C2: Acetaminophen 1g/100ml | D2: Acetphen 1g/100ml premix inj | E2: 1bag | F2: 실온보관(1~30℃), 밀봉용기 | H2: 1
A3: 2 | B3: ASP1PR | C3: Aspirin enteric coated 100mg tab | D3: Aspirin protect 100mg tab | E3: 1500TAB/BOX | F3: 기밀용기, 실온(25℃이하)보관 | H3: 3
A4: 3 | B4: XNICAR5 | D4: Binicapin 5mg/5ml inj | F4: 차광, 실온(1~30℃)보관 | H4: 1
A5: 4 | B5: XPCMOL | C5: Propacetamol 1g | D5: Denogan 1g inj | E5: 10VIA/BOX | F5: 차광밀봉용기, 1~25℃보관 | H5: 4
A6: 5 | B6: XDILT | C6: Diltiazem 50mg inj | D6: Herben 50mg inj | E6: 10VIA/BOX | F6: 밀봉용기, 실온보존(1～30℃) | H6: 1
A7: 6 | B7: XHYOS2Y | C7: Hyspan 20mg inj | D7: Hyspan 20mg inj | E7: 50AMP/BOX | F7: 차광밀봉용기, 실온(1~30℃)보관 | H7: 1
A8: 7 | B8: XKROL | C8: Ketorolac tromethamine 30mg | D8: Keromin 30mg Inj | E8: 50AMP/BOX | F8: 차광밀봉용기, 실온(1-30℃)보관 | H8: 2
A9: 8 | B9: XFURO | C9: Furosemide 20mg | D9: Lasix 20mg inj | E9: 50AMP/BOX | F9: 밀봉용기 실온보관 차광. | G9: =VLOOKUP(B9,'비품현황표(전체)'!$A$1:$F$273,6,0) -> 유사모양 | H9: 2
A10: 9 | B10: XMEXO | C10: Metoclopramide | D10: Macperan 10mg inj | E10: 50AMP/BOX | F10: 밀봉용기, 차광, 실온(1~30℃)보관 | H10: 2
A11: 10 | B11: XESOME40 | C11: Esomerazole sodium | D11: Nexium 40mg inj. | E11: 40MG/VIAL*10*12 | F11: 밀봉용기, 차광하여 30℃이하 보관 | H11: 1
A12: 11 | B12: NITR | C12: nitroglycerin | D12: Nitroglycerine 0.6mg tab | F12: 차광 기밀용기, 20도이하보관 | H12: 2
A13: 12 | B13: XNITR10F | C13: Nitroglycerin 10mg | D13: Nitrolingual 10mg inj | E13: 10 AMP/BOX | F13: 밀봉용기, 실온보관 | G13: =VLOOKUP(B13,'비품현황표(전체)'!$A$1:$F$273,6,0) -> 유사모양 | H13: 1
A14: 13 | B14: XPANTO4 | C14: Pantoprazole 40mg inj. | D14: Pantoline 40mg inj | E14: 1VIAL/BOX | F14: 차광밀봉용기, 25℃ 이하 | H14: 1
A15: 14 | B15: XCPENIR | C15: Chlorpheniramine | D15: Peniramin 4mg/2ml inj | E15: 100AMP/BOX | F15: 밀봉용기 | H15: 1
A16: 15 | B16: CLOPID | C16: Clopidogrel 75mg | D16: Plavix 75mg tab | E16: 100TAB/BTL | F16: 기밀용기, 실온보관(1~30℃) | G16: =VLOOKUP(B16,'비품현황표(전체)'!$A$1:$F$273,6,0) -> 유사모양 | H16: 10
A17: 16 | B17: XTAZOC4W | C17: Piperacillin sod 4g/Tazobactam 0.5g | D17: Tazoractam 4.5g inj | E17: 10VIAL/BOX | F17: 밀봉용기, 실온(1-30℃) 보관 | H17: 1
A18: 17 | B18: XTRAM50 | C18: Tramadol 50mg/ml | D18: Tridol 50mg inj | E18: 50AMP/BOX | F18: 밀봉용기, 실온(1～30℃)보관 | H18: 3
D19: 보유비품약 품목수 | H19: 17

Sheet 62
A1: NO | B1: 약품코드 | C1: 일반명 | D1: 영문상품명 | E1: 규격 | F1: 보관조건 | G1: 혼돈주의약품 | H1: 23.01.17
A2: 1 | B2: XPALON75 | C2: Palonosetron 0.075mg/1.5ml | D2: Aloxi 0.075mg/1.5ml inj | E2: 5vial/BOX | F2: 실온(1∼30℃)보관, 밀봉용기, 빛을 피하여 보관 | G2: =VLOOKUP(B2,'비품현황표(전체)'!$A$1:$F$273,6, ) -> 용량고주의 | H2: 1
A3: 2 | B3: XAMBR15 | C3: Ambroxol 15mg | D3: Ambroxol 15mg inj | E3: 50AMP/BOX | F3: 차광밀봉용기, 실온(1~30℃)보관 | G3: 유사모양 | H3: 2
A4: 3 | B4: XNICAR5 | D4: Binicapin 5mg/5ml inj | F4: 차광, 실온(1~30℃)보관 | H4: 2
A5: 4 | B5: XPCMOL | C5: Propacetamol 1g | D5: Denogan 1g inj | E5: 10VIA/BOX | F5: 차광밀봉용기, 1~25℃보관 | H5: 6
A6: 5 | B6: XDXM | C6: Dexamethasone 5mg | D6: Dexamethasone 5mg inj | E6: 50AMP/BOX | F6: 차광한 밀봉용기, 실온(1 ~ 30℃) 보관 | G6: =VLOOKUP(B6,'비품현황표(전체)'!$A$1:$F$273,6, ) -> 유사발음 | H6: 3
A7: 6 | B7: XCZEDO2G | C7: Cefazedone 2g | D7: Fazidone 2g inj | E7: 10VIA/BOX | F7: 밀봉용기,실온(1~30℃)보관 | H7: 1
A8: 7 | B8: XFAMO2W | C8: Famotidine 20mg inj | D8: Gaster 20mg/10ml inj | E8: 10AMP/BOX*10 | F8: 밀봉용기, 실온보관(1~30℃) | H8: 2
A9: 8 | B9: XHYOS2Y | C9: Hyspan 20mg inj | D9: Hyspan 20mg inj | E9: 50AMP/BOX | F9: 차광밀봉용기, 실온(1~30℃)보관 | H9: 1
A10: 9 | B10: XKROL | C10: Ketorolac tromethamine 30mg | D10: Keromin 30mg Inj | E10: 50AMP/BOX | F10: 차광밀봉용기, 실온(1-30℃)보관 | H10: 5
A11: 10 | B11: XFURO | C11: Furosemide 20mg | D11: Lasix 20mg inj | E11: 50AMP/BOX | F11: 밀봉용기 실온보관 차광. | G11: =VLOOKUP(B11,'비품현황표(전체)'!$A$1:$F$273,6, ) -> 유사모양 | H11: 1
A12: 11 | B12: XMEXO | C12: Metoclopramide | D12: Macperan 10mg inj | E12: 50AMP/BOX | F12: 밀봉용기, 차광, 실온(1~30℃)보관 | H12: 5
A13: 12 | B13: XCMINX | C13: Cefminox sodium 1g | D13: Meicelin 1g inj | E13: 10VIA/BOX | F13: 밀봉용기, 실온보관 | H13: 2
A14: 13 | B14: XPANTO4 | C14: Pantoprazole 40mg inj. | D14: Pantoline 40mg inj | E14: 1VIAL/BOX | F14: 차광밀봉용기, 25℃ 이하 | H14: 2
A15: 14 | B15: XCPENIR | C15: Chlorpheniramine | D15: Peniramin 4mg/2ml inj | E15: 100AMP/BOX | F15: 밀봉용기 | H15: 1
A16: 15 | B16: XHPD | C16: Haloperidol 5mg/1ml | D16: Peridol 5mg inj | E16: 10AMP/BOX | F16: 밀봉용기, 차광하여 실온보관 | G16: =VLOOKUP(B16,'비품현황표(전체)'!$A$1:$F$273,6, ) -> 유사발음 | H16: 1
A17: 16 | B17: XTAZOC4W | C17: Piperacillin sod 4g/Tazobactam 0.5g | D17: Tazoractam 4.5g inj | E17: 10VIAL/BOX | F17: 밀봉용기, 실온(1-30℃) 보관 | H17: 1
A18: 17 | B18: XTRAM50 | C18: Tramadol 50mg/ml | D18: Tridol 50mg inj | E18: 50AMP/BOX | F18: 밀봉용기, 실온(1～30℃)보관 | H18: 5
D19: 보유비품약 품목수 | H19: 17

Sheet 71
A1: NO | B1: 약품코드 | C1: 일반명 | D1: 영문상품명 | E1: 규격 | F1: 보관조건 | G1: 혼돈주의약품 | H1: 25.06.11
A2: 1 | B2: IPRAT-RS | C2: Ipratropium bromide inh.soln 500mcg/2ml | D2: Atrovent UDV 2ml/Amp | E2: 20AMP/BOX*54 | F2: 밀봉용기, 실온보관 | G2: =VLOOKUP(B2,'비품현황표(전체)'!$A$1:$F$273,6, ) -> 유사모양 | H2: 1
A3: 2 | B3: XNICAR5 | D3: Binicapin 5mg/5ml inj | F3: 차광, 실온(1~30℃)보관 | H3: 2
A4: 3 | B4: XCAGL | C4: Calcium gluconate 9.29mEq/amp | D4: Calcium gluconate 2g inj | E4: 50AMP/BOX | F4: 밀봉용기, 실온(1 - 30℃)보관 | H4: 2
A5: 4 | B5: XAMIOD | C5: Amiodarone 150mg | D5: Cordarone 150mg/3ml inj | E5: 6AMP/BOX | F5: 밀봉용기 | H5: 4
A6: 5 | B6: XPCMOL | C6: Propacetamol 1g | D6: Denogan 1g inj | E6: 10VIA/BOX | F6: 차광밀봉용기, 1~25℃보관 | H6: 5
A7: 6 | B7: XKROL | C7: Ketorolac tromethamine 30mg | D7: Keromin 30mg Inj | E7: 50AMP/BOX | F7: 차광밀봉용기, 실온(1-30℃)보관 | H7: 2
A8: 7 | B8: XFURO | C8: Furosemide 20mg | D8: Lasix 20mg inj | E8: 50AMP/BOX | F8: 밀봉용기 실온보관 차광. | G8: =VLOOKUP(B8,'비품현황표(전체)'!$A$1:$F$273,6, ) -> 유사모양 | H8: 2
A9: 8 | B9: XMEXO | C9: Metoclopramide | D9: Macperan 10mg inj | E9: 50AMP/BOX | F9: 밀봉용기, 차광, 실온(1~30℃)보관 | H9: 5
A10: 9 | B10: ACYST-A | C10: Acetylcysteine 20% 4ml sol | D10: Mucomyst 20% 4ml sol | E10: 10VIA/BOX | F10: 기밀용기,실온에서 차광보존 | G10: =VLOOKUP(B10,'비품현황표(전체)'!$A$1:$F$273,6, ) -> 유사모양 | H10: 1
A11: 10 | B11: XNITR10F | C11: Nitroglycerin 10mg | D11: Nitrolingual 10mg inj | E11: 10 AMP/BOX | F11: 밀봉용기, 실온보관 | G11: =VLOOKUP(B11,'비품현황표(전체)'!$A$1:$F$273,6, ) -> 유사모양 | H11: 1
A12: 11 | B12: XNORE10 | C12: Norepinephrine 10mg/10ml | D12: Norpin 10mg inj | E12: 10AMP/BOX | F12: 차광밀봉용기, 실온보관(1-30) | H12: 3
A13: 12 | B13: XCPENIR | C13: Chlorpheniramine | D13: Peniramin 4mg/2ml inj | E13: 100AMP/BOX | F13: 밀봉용기 | H13: 1
A14: 13 | B14: XHPD | C14: Haloperidol 5mg/1ml | D14: Peridol 5mg inj | E14: 10AMP/BOX | F14: 밀봉용기, 차광하여 실온보관 | G14: =VLOOKUP(B14,'비품현황표(전체)'!$A$1:$F$273,6, ) -> 유사발음 | H14: 1
A15: 14 | B15: BUD2-RP | C15: Budesonide nebulizer 0.5mg/2ml amp | D15: Pulmican sus 0.5mg/2ml amp | E15: 30AMP/BOX | F15: 기밀용기, 실온(1~30℃)보관 | G15: =VLOOKUP(B15,'비품현황표(전체)'!$A$1:$F$273,6, ) -> 유사모양 | H15: 1
A16: 15 | B16: XTRAM50 | C16: Tramadol 50mg/ml | D16: Tridol 50mg inj | E16: 50AMP/BOX | F16: 밀봉용기, 실온(1～30℃)보관 | H16: 5
D17: 보유비품약 품목수 | H17: 15

Sheet 72
A1: NO | B1: 약품코드 | C1: 일반명 | D1: 영문상품명 | E1: 규격 | F1: 보관조건 | G1: 혼돈주의약품 | H1: 26.06.01
A2: 1 | B2: XAPH1 | C2: Acetaminophen 1g/100ml | D2: Acetphen 1g/100ml premix inj | E2: 1bag | F2: 실온보관(1~30℃), 밀봉용기 | H2: 1
A3: 2 | B3: XNICAR5 | D3: Binicapin 5mg/5ml inj | F3: 차광, 실온(1~30℃)보관 | H3: 1
A4: 3 | B4: XPCMOL | C4: Propacetamol 1g | D4: Denogan 1g inj | E4: 10VIA/BOX | F4: 차광밀봉용기, 1~25℃보관 | H4: 5
A5: 4 | B5: XDXM | C5: Dexamethasone 5mg | D5: Dexamethasone 5mg inj | E5: 50AMP/BOX | F5: 차광한 밀봉용기, 실온(1 ~ 30℃) 보관 | G5: =VLOOKUP(B5,'비품현황표(전체)'!$A$1:$F$273,6, ) -> 유사발음 | H5: 1
A6: 5 | B6: XHYOS2Y | C6: Hyspan 20mg inj | D6: Hyspan 20mg inj | E6: 50AMP/BOX | F6: 차광밀봉용기, 실온(1~30℃)보관 | H6: 1
A7: 6 | B7: XKROL | C7: Ketorolac tromethamine 30mg | D7: Keromin 30mg Inj | E7: 50AMP/BOX | F7: 차광밀봉용기, 실온(1-30℃)보관 | H7: 5
A8: 7 | B8: XFURO | C8: Furosemide 20mg | D8: Lasix 20mg inj | E8: 50AMP/BOX | F8: 밀봉용기 실온보관 차광. | G8: =VLOOKUP(B8,'비품현황표(전체)'!$A$1:$F$273,6, ) -> 유사모양 | H8: 1
A9: 8 | B9: XMEXO | C9: Metoclopramide | D9: Macperan 10mg inj | E9: 50AMP/BOX | F9: 밀봉용기, 차광, 실온(1~30℃)보관 | H9: 5
A10: 9 | B10: XNITR10F | C10: Nitroglycerin 10mg | D10: Nitrolingual 10mg inj | E10: 10 AMP/BOX | F10: 밀봉용기, 실온보관 | G10: =VLOOKUP(B10,'비품현황표(전체)'!$A$1:$F$273,6, ) -> 유사모양 | H10: 1
A11: 10 | B11: XNORE10 | C11: Norepinephrine 10mg/10ml | D11: Norpin 10mg inj | E11: 10AMP/BOX | F11: 차광밀봉용기, 실온보관(1-30) | H11: 3
A12: 11 | B12: XCPENIR | C12: Chlorpheniramine | D12: Peniramin 4mg/2ml inj | E12: 100AMP/BOX | F12: 밀봉용기 | H12: 1
A13: 12 | B13: XHPD | C13: Haloperidol 5mg/1ml | D13: Peridol 5mg inj | E13: 10AMP/BOX | F13: 밀봉용기, 차광하여 실온보관 | G13: =VLOOKUP(B13,'비품현황표(전체)'!$A$1:$F$273,6, ) -> 유사발음 | H13: 3
A14: 13 | B14: BUD2-RP | C14: Budesonide nebulizer 0.5mg/2ml amp | D14: Pulmican sus 0.5mg/2ml amp | E14: 30AMP/BOX | F14: 기밀용기, 실온(1~30℃)보관 | G14: 유사모양 | H14: 1
A15: 14 | B15: XTRAM50 | C15: Tramadol 50mg/ml | D15: Tridol 50mg inj | E15: 50AMP/BOX | F15: 밀봉용기, 실온(1～30℃)보관 | H15: 5
A16: 15 | B16: SALB-NB | C16: Salbutamol inhalation nebule 2.5mg | D16: Ventolin nebule 2.5mg | E16: 20AMP/BOX*54 | F16: 기밀용기, 30℃이하 차광보관 | G16: 유사모양 | H16: 1
D17: 보유비품약 품목수 | H17: 15

Sheet 81
A1: NO | B1: 약품코드 | C1: 일반명 | D1: 영문상품명 | E1: 규격 | F1: 보관조건 | G1: 혼돈주의약품 | H1: 25.10.16
A2: 1 | B2: XAPH1 | C2: Acetaminophen 1g/100ml | D2: Acetphen 1g/100ml premix inj | E2: 1bag | F2: 실온보관(1~30℃), 밀봉용기 | H2: 2
A3: 2 | B3: XNICAR5 | D3: Binicapin 5mg/5ml inj | F3: 차광, 실온(1~30℃)보관 | G3: =IF(VLOOKUP(B3,'비품현황표(전체)'!$A$1:$F$273,6,FALSE)=0,"",VLOOKUP(B3,'비품현황표(전체)'!$A$1:$F$273,6,FALSE)) | H3: 2
A4: 3 | B4: XPCMOL | C4: Propacetamol 1g | D4: Denogan 1g inj | E4: 10VIA/BOX | F4: 차광밀봉용기, 1~25℃보관 | G4: =IF(VLOOKUP(B4,'비품현황표(전체)'!$A$1:$F$273,6,FALSE)=0,"",VLOOKUP(B4,'비품현황표(전체)'!$A$1:$F$273,6,FALSE)) | H4: 6
A5: 4 | B5: XDICLOF | C5: diclofenac-β-dimethyl-aminoethanol 90mg/2ml | D5: Dibeta-C 90mg/2ml inj | E5: 50AMP/BOX | F5: 차광밀봉용기, 실온(1~30℃)보관 | G5: =IF(VLOOKUP(B5,'비품현황표(전체)'!$A$1:$F$273,6,FALSE)=0,"",VLOOKUP(B5,'비품현황표(전체)'!$A$1:$F$273,6,FALSE)) | H5: 6
A6: 5 | B6: XKROL | C6: Ketorolac tromethamine 30mg | D6: Keromin 30mg Inj | E6: 50AMP/BOX | F6: 차광밀봉용기, 실온(1-30℃)보관 | G6: =IF(VLOOKUP(B6,'비품현황표(전체)'!$A$1:$F$273,6,FALSE)=0,"",VLOOKUP(B6,'비품현황표(전체)'!$A$1:$F$273,6,FALSE)) | H6: 3
A7: 6 | B7: XMEXO | C7: Metoclopramide | D7: Macperan 10mg inj | E7: 50AMP/BOX | F7: 밀봉용기, 차광, 실온(1~30℃)보관 | G7: =IF(VLOOKUP(B7,'비품현황표(전체)'!$A$1:$F$273,6,FALSE)=0,"",VLOOKUP(B7,'비품현황표(전체)'!$A$1:$F$273,6,FALSE)) | H7: 4
A8: 7 | B8: PANCR457 | C8: Norzyme cap (pancreatin) | D8: Norzyme cap | E8: 100Cap/BTL | F8: 기밀용기, 실온(1~30℃)보관 | H8: 2
A9: 8 | B9: XCPENIR | C9: Chlorpheniramine | D9: Peniramin 4mg/2ml inj | E9: 100AMP/BOX | F9: 밀봉용기 | G9: =IF(VLOOKUP(B9,'비품현황표(전체)'!$A$1:$F$273,6,FALSE)=0,"",VLOOKUP(B9,'비품현황표(전체)'!$A$1:$F$273,6,FALSE)) | H9: 2
A10: 9 | B10: APH6ER1Y | C10: Acetaminophen ER 650mg | D10: Tramol ER 650mg tab | E10: 500TAB/BTL | F10: 밀폐용기 실온보관 | G10: =IF(VLOOKUP(B10,'비품현황표(전체)'!$A$1:$F$273,6,FALSE)=0,"",VLOOKUP(B10,'비품현황표(전체)'!$A$1:$F$273,6,FALSE)) | H10: 4
A11: 10 | B11: XTRAM50 | C11: Tramadol 50mg/ml | D11: Tridol 50mg inj | E11: 50AMP/BOX | F11: 밀봉용기, 실온(1～30℃)보관 | G11: =IF(VLOOKUP(B11,'비품현황표(전체)'!$A$1:$F$273,6,FALSE)=0,"",VLOOKUP(B11,'비품현황표(전체)'!$A$1:$F$273,6,FALSE)) | H11: 6
D12: 보유비품약 품목수 | H12: 10

Sheet 82
A1: NO | B1: 약품코드 | C1: 일반명 | D1: 영문상품명 | E1: 규격 | F1: 보관조건 | G1: 혼돈주의약품 | H1: 26.03.06
A2: 1 | B2: XAPH1 | C2: Acetaminophen 1g/100ml | D2: Acetphen 1g/100ml premix inj | E2: 1bag | F2: 실온보관(1~30℃), 밀봉용기 | H2: 2
A3: 2 | B3: XNICAR5 | C3: Binicapin 5mg/5ml inj | D3: Binicapin 5mg/5ml inj | F3: 차광, 실온(1~30℃)보관 | G3: =IF(VLOOKUP(B3,'비품현황표(전체)'!$A$1:$F$273,6,FALSE)=0,"",VLOOKUP(B3,'비품현황표(전체)'!$A$1:$F$273,6,FALSE)) | H3: 2
A4: 3 | B4: XPCMOL | C4: Denogan 1g inj | D4: Denogan 1g inj | F4: 차광밀봉용기, 1~25℃보관 | G4: =IF(VLOOKUP(B4,'비품현황표(전체)'!$A$1:$F$273,6,FALSE)=0,"",VLOOKUP(B4,'비품현황표(전체)'!$A$1:$F$273,6,FALSE)) | H4: 4
A5: 4 | B5: XDXM | C5: Dexamethasone 5mg inj | D5: Dexamethasone 5mg inj | E5: 유사발음 | F5: 차광한 밀봉용기, 실온(1 ~ 30℃) 보관 | G5: =IF(VLOOKUP(B5,'비품현황표(전체)'!$A$1:$F$273,6,FALSE)=0,"",VLOOKUP(B5,'비품현황표(전체)'!$A$1:$F$273,6,FALSE)) -> 유사발음 | H5: 2
A6: 5 | B6: XKROL | C6: Keromin 30mg Inj | D6: Keromin 30mg Inj | F6: 차광밀봉용기, 실온(1-30℃)보관 | G6: =IF(VLOOKUP(B6,'비품현황표(전체)'!$A$1:$F$273,6,FALSE)=0,"",VLOOKUP(B6,'비품현황표(전체)'!$A$1:$F$273,6,FALSE)) | H6: 3
A7: 6 | B7: XFURO | C7: Lasix 20mg inj | D7: Lasix 20mg inj | E7: 유사모양 | F7: 밀봉용기 실온보관 차광. | G7: =IF(VLOOKUP(B7,'비품현황표(전체)'!$A$1:$F$273,6,FALSE)=0,"",VLOOKUP(B7,'비품현황표(전체)'!$A$1:$F$273,6,FALSE)) -> 유사모양 | H7: 1
A8: 7 | B8: XMEXO | C8: Macperan 10mg inj | D8: Macperan 10mg inj | F8: 밀봉용기, 차광, 실온(1~30℃)보관 | G8: =IF(VLOOKUP(B8,'비품현황표(전체)'!$A$1:$F$273,6,FALSE)=0,"",VLOOKUP(B8,'비품현황표(전체)'!$A$1:$F$273,6,FALSE)) | H8: 3
A9: 8 | B9: XPANTO4 | C9: Pantoline 40mg inj | D9: Pantoline 40mg inj | F9: 차광밀봉용기, 25℃ 이하 | G9: =IF(VLOOKUP(B9,'비품현황표(전체)'!$A$1:$F$273,6,FALSE)=0,"",VLOOKUP(B9,'비품현황표(전체)'!$A$1:$F$273,6,FALSE)) | H9: 2
A10: 9 | B10: XCPENIR | C10: Peniramin 4mg/2ml inj | D10: Peniramin 4mg/2ml inj | F10: 밀봉용기 | G10: =IF(VLOOKUP(B10,'비품현황표(전체)'!$A$1:$F$273,6,FALSE)=0,"",VLOOKUP(B10,'비품현황표(전체)'!$A$1:$F$273,6,FALSE)) | H10: 2
A11: 10 | B11: XHPD | C11: Peridol 5mg inj | D11: Peridol 5mg inj | E11: 유사발음 | F11: 밀봉용기, 차광하여 실온보관 | G11: =IF(VLOOKUP(B11,'비품현황표(전체)'!$A$1:$F$273,6,FALSE)=0,"",VLOOKUP(B11,'비품현황표(전체)'!$A$1:$F$273,6,FALSE)) -> 유사발음 | H11: 1
A12: 11 | B12: XTAZOC4W | C12: Tazoractam 4.5g inj | D12: Tazoractam 4.5g inj | F12: 밀봉용기, 실온(1-30℃) 보관 | G12: =IF(VLOOKUP(B12,'비품현황표(전체)'!$A$1:$F$273,6,FALSE)=0,"",VLOOKUP(B12,'비품현황표(전체)'!$A$1:$F$273,6,FALSE)) | H12: 1
A13: 12 | B13: XTRAM50 | C13: Tridol 50mg inj | D13: Tridol 50mg inj | F13: 밀봉용기, 실온(1～30℃)보관 | G13: =IF(VLOOKUP(B13,'비품현황표(전체)'!$A$1:$F$273,6,FALSE)=0,"",VLOOKUP(B13,'비품현황표(전체)'!$A$1:$F$273,6,FALSE)) | H13: 3
D14: 보유비품약 품목수 | H14: 12

Sheet Sheet5

Sheet 91
A1: NO | B1: 약품코드 | C1: 일반명 | D1: 영문상품명 | E1: 규격 | F1: 보관조건 | G1: 혼돈주의약품 | H1: 24.03.18
A2: 1 | B2: XAPH1 | C2: Acetaminophen 1g/100ml | D2: Acetphen 1g/100ml premix inj | E2: 1bag | F2: 실온보관(1~30℃), 밀봉용기 | G2: =IF(VLOOKUP(B2,'비품현황표(전체)'!$A$1:$F$273,6,FALSE)=0,"",VLOOKUP(B2,'비품현황표(전체)'!$A$1:$F$273,6,FALSE))
A3: 2 | B3: XPALON75 | C3: Ipratropium bromide inh.soln 500mcg/2ml | D3: Aloxi 0.075mg/1.5ml inj | E3: 20AMP/BOX*54 | F3: 실온(1∼30℃)보관, 밀봉용기, 빛을 피하여 보관 | G3: =IF(VLOOKUP(B3,'비품현황표(전체)'!$A$1:$F$273,6,FALSE)=0,"",VLOOKUP(B3,'비품현황표(전체)'!$A$1:$F$273,6,FALSE)) -> 용량고주의
A4: 3 | B4: XNICAR5 | D4: Binicapin 5mg/5ml inj | F4: 차광, 실온(1~30℃)보관 | G4: =IF(VLOOKUP(B4,'비품현황표(전체)'!$A$1:$F$273,6,FALSE)=0,"",VLOOKUP(B4,'비품현황표(전체)'!$A$1:$F$273,6,FALSE))
A5: 4 | B5: XCZEDO | C5: Cefazolin 1g inj | D5: Cefazedone 1g inj | E5: 10VIA/BOX | F5: 밀봉용기, 실온보관 | G5: =IF(VLOOKUP(B5,'비품현황표(전체)'!$A$1:$F$273,6,FALSE)=0,"",VLOOKUP(B5,'비품현황표(전체)'!$A$1:$F$273,6,FALSE))
A6: 5 | B6: XCZOL1X | C6: Propacetamol 1g | D6: Cefazolin 1g inj | E6: 10VIA/BOX | F6: 밀봉용기, 실온보관 | G6: =IF(VLOOKUP(B6,'비품현황표(전체)'!$A$1:$F$273,6,FALSE)=0,"",VLOOKUP(B6,'비품현황표(전체)'!$A$1:$F$273,6,FALSE)) -> #N/A
A7: 6 | B7: XPCMOL | C7: Dexamethasone 5mg | D7: Denogan 1g inj | E7: 50AMP/BOX | F7: 차광밀봉용기, 1~25℃보관 | G7: =IF(VLOOKUP(B7,'비품현황표(전체)'!$A$1:$F$273,6,FALSE)=0,"",VLOOKUP(B7,'비품현황표(전체)'!$A$1:$F$273,6,FALSE))
A8: 7 | B8: XDXM | C8: diclofenac-β-dimethyl-aminoethanol 90mg/2ml | D8: Dexamethasone 5mg inj | E8: 50AMP/BOX | F8: 차광한 밀봉용기, 실온(1 ~ 30℃) 보관 | G8: =IF(VLOOKUP(B8,'비품현황표(전체)'!$A$1:$F$273,6,FALSE)=0,"",VLOOKUP(B8,'비품현황표(전체)'!$A$1:$F$273,6,FALSE)) -> 유사발음
A9: 8 | B9: XDICLOF | C9: Levetiracetam 500mg | D9: Dibeta-C 90mg/2ml inj | E9: 10vial/BOX | F9: 차광밀봉용기, 실온(1~30℃)보관 | G9: =IF(VLOOKUP(B9,'비품현황표(전체)'!$A$1:$F$273,6,FALSE)=0,"",VLOOKUP(B9,'비품현황표(전체)'!$A$1:$F$273,6,FALSE))
A10: 9 | B10: XLEVET500W | C10: Cefazedone 2g | D10: Epilatam 500mg inj | E10: 10VIA/BOX | F10: 밀봉용기, 실온(1~30℃)보관 | G10: =IF(VLOOKUP(B10,'비품현황표(전체)'!$A$1:$F$273,6,FALSE)=0,"",VLOOKUP(B10,'비품현황표(전체)'!$A$1:$F$273,6,FALSE)) -> 유사발음
A11: 10 | B11: XCZEDO2G | C11: Ketorolac tromethamine 30mg | D11: Fazidone 2g inj | E11: 50AMP/BOX | F11: 밀봉용기,실온(1~30℃)보관 | G11: =IF(VLOOKUP(B11,'비품현황표(전체)'!$A$1:$F$273,6,FALSE)=0,"",VLOOKUP(B11,'비품현황표(전체)'!$A$1:$F$273,6,FALSE))
A12: 11 | B12: XDILT | C12: Diltiazem 50mg inj | D12: Herben 50mg inj | E12: 10VIA/BOX | F12: 밀봉용기, 실온보존(1～30℃) | G12: =IF(VLOOKUP(B12,'비품현황표(전체)'!$A$1:$F$273,6,FALSE)=0,"",VLOOKUP(B12,'비품현황표(전체)'!$A$1:$F$273,6,FALSE))
A13: 12 | B13: XKROL | C13: Labetalol HCl 20mg inj | D13: Keromin 30mg Inj | E13: 50AMP/BOX | F13: 차광밀봉용기, 실온(1-30℃)보관 | G13: =IF(VLOOKUP(B13,'비품현황표(전체)'!$A$1:$F$273,6,FALSE)=0,"",VLOOKUP(B13,'비품현황표(전체)'!$A$1:$F$273,6,FALSE))
A14: 13 | B14: XFURO | C14: Furosemide 20mg | D14: Lasix 20mg inj | E14: 50AMP/BOX | F14: 밀봉용기 실온보관 차광. | G14: =IF(VLOOKUP(B14,'비품현황표(전체)'!$A$1:$F$273,6,FALSE)=0,"",VLOOKUP(B14,'비품현황표(전체)'!$A$1:$F$273,6,FALSE)) -> 유사모양
A15: 14 | B15: XMEXO | C15: Acetylcysteine 20% 4ml sol | D15: Macperan 10mg inj | E15: 10VIA/BOX | F15: 밀봉용기, 차광, 실온(1~30℃)보관 | G15: =IF(VLOOKUP(B15,'비품현황표(전체)'!$A$1:$F$273,6,FALSE)=0,"",VLOOKUP(B15,'비품현황표(전체)'!$A$1:$F$273,6,FALSE))
A16: 15 | B16: X20M1X | C16: NaCl 40mEq/20ml plastic amp | D16: Mannitol 20% 100ml bag대한 | E16: 50AMP/BOX | F16: 밀봉용기 | G16: =IF(VLOOKUP(B16,'비품현황표(전체)'!$A$1:$F$273,6,FALSE)=0,"",VLOOKUP(B16,'비품현황표(전체)'!$A$1:$F$273,6,FALSE))
... A18: 17 | B18: XRAMOSET | C18: Nicardipine 10mg | D18: Nasea 0.3mg inj | E18: 10AMP/BOX | F18: 밀봉용기, 차광보존, 실온(1~30℃)보관 | G18: =IF(VLOOKUP(B18,'비품현황표(전체)'!$A$1:$F$273,6,FALSE)=0,"",VLOOKUP(B18,'비품현황표(전체)'!$A$1:$F$273,6,FALSE))
A19: 18 | B19: XCPENIR | C19: Chlorpheniramine | D19: Peniramin 4mg/2ml inj | E19: 100AMP/BOX | F19: 밀봉용기
A20: 19 | B20: XPSPA | C20: Haloperidol 5mg/1ml | D20: Pentastarch 10% 500mL inj | E20: 10AMP/BOX | F20: 밀봉용기, 25℃이하, | G20: =IF(VLOOKUP(B20,'비품현황표(전체)'!$A$1:$F$273,6,FALSE)=0,"",VLOOKUP(B20,'비품현황표(전체)'!$A$1:$F$273,6,FALSE)) -> #N/A
A21: 20 | B21: XHPD | C21: Salbutamol inhalation nebule 2.5mg | D21: Peridol 5mg inj | E21: 20AMP/BOX*54 | F21: 밀봉용기, 차광하여 실온보관 | G21: =IF(VLOOKUP(B21,'비품현황표(전체)'!$A$1:$F$273,6,FALSE)=0,"",VLOOKUP(B21,'비품현황표(전체)'!$A$1:$F$273,6,FALSE)) -> 유사발음
A22: 21 | B22: XTRAM50 | D22: Tridol 50mg inj | F22: 밀봉용기, 실온(1～30℃)보관 | G22: =IF(VLOOKUP(B22,'비품현황표(전체)'!$A$1:$F$273,6,FALSE)=0,"",VLOOKUP(B22,'비품현황표(전체)'!$A$1:$F$273,6,FALSE))
D23: 보유비품약 품목수 | H23: 21

Sheet 92
A1: NO | B1: 약품코드 | C1: 일반명 | D1: 영문상품명 | E1: 규격 | F1: 보관조건 | G1: 혼돈주의약품 | H1: 25.07.18
A2: 1 | B2: XAPH1 | C2: Acetaminophen 1g/100ml | D2: Acetphen 1g/100ml premix inj | E2: 1bag | F2: 실온보관(1~30℃), 밀봉용기 | H2: 2
A3: 2 | B3: XNICAR5 | D3: Binicapin 5mg/5ml inj | F3: 차광, 실온(1~30℃)보관 | G3: =IF(VLOOKUP(B3,'비품현황표(전체)'!$A$1:$F$273,6,FALSE)=0,"",VLOOKUP(B3,'비품현황표(전체)'!$A$1:$F$273,6,FALSE)) | H3: 2
A4: 3 | B4: XCZEDO | C4: Cefazedone 1g | D4: Cefazedone 1g inj | E4: 10VIA/BOX | F4: 밀봉용기, 실온보관 | G4: =IF(VLOOKUP(B4,'비품현황표(전체)'!$A$1:$F$273,6,FALSE)=0,"",VLOOKUP(B4,'비품현황표(전체)'!$A$1:$F$273,6,FALSE)) | H4: 2
A5: 4 | B5: XCZOL1W | C5: Cefazolin 1g inj | D5: Cefazolin 1g inj | E5: 10VIA/BOX | F5: 밀봉용기, 실온보관 | G5: =IF(VLOOKUP(B5,'비품현황표(전체)'!$A$1:$F$273,6,FALSE)=0,"",VLOOKUP(B5,'비품현황표(전체)'!$A$1:$F$273,6,FALSE)) | H5: 2
A6: 5 | B6: XPCMOL | C6: Propacetamol 1g | D6: Denogan 1g inj | E6: 10VIA/BOX | F6: 차광밀봉용기, 1~25℃보관 | G6: =IF(VLOOKUP(B6,'비품현황표(전체)'!$A$1:$F$273,6,FALSE)=0,"",VLOOKUP(B6,'비품현황표(전체)'!$A$1:$F$273,6,FALSE)) | H6: 8
A7: 6 | B7: XDXM | C7: Dexamethasone 5mg | D7: Dexamethasone 5mg inj | E7: 50AMP/BOX | F7: 차광한 밀봉용기, 실온(1 ~ 30℃) 보관 | G7: =IF(VLOOKUP(B7,'비품현황표(전체)'!$A$1:$F$273,6,FALSE)=0,"",VLOOKUP(B7,'비품현황표(전체)'!$A$1:$F$273,6,FALSE)) -> 유사발음 | H7: 2
A8: 7 | B8: XDICLOF | C8: diclofenac-β-dimethyl-aminoethanol 90mg/2ml | D8: Dibeta-C 90mg/2ml inj | E8: 50AMP/BOX | F8: 차광밀봉용기, 실온(1~30℃)보관 | G8: =IF(VLOOKUP(B8,'비품현황표(전체)'!$A$1:$F$273,6,FALSE)=0,"",VLOOKUP(B8,'비품현황표(전체)'!$A$1:$F$273,6,FALSE)) | H8: 2
A9: 8 | B9: XLEVET500W | C9: Levetiracetam 500mg | D9: Epilatam 500mg inj | E9: 10vial/BOX | F9: 밀봉용기, 실온(1~30℃)보관 | G9: 유사발음 | H9: 2
A10: 9 | B10: XCZEDO2G | C10: Cefazedone 2g | D10: Fazidone 2g inj | E10: 10VIA/BOX | F10: 밀봉용기,실온(1~30℃)보관 | G10: =IF(VLOOKUP(B10,'비품현황표(전체)'!$A$1:$F$273,6,FALSE)=0,"",VLOOKUP(B10,'비품현황표(전체)'!$A$1:$F$273,6,FALSE)) | H10: 2
A11: 10 | B11: XKROL | C11: Ketorolac tromethamine 30mg | D11: Keromin 30mg Inj | E11: 50AMP/BOX | F11: 차광밀봉용기, 실온(1-30℃)보관 | G11: =IF(VLOOKUP(B11,'비품현황표(전체)'!$A$1:$F$273,6,FALSE)=0,"",VLOOKUP(B11,'비품현황표(전체)'!$A$1:$F$273,6,FALSE)) | H11: 2
A12: 11 | B12: XFURO | C12: Furosemide 20mg | D12: Lasix 20mg inj | E12: 50AMP/BOX | F12: 밀봉용기 실온보관 차광. | G12: =IF(VLOOKUP(B12,'비품현황표(전체)'!$A$1:$F$273,6,FALSE)=0,"",VLOOKUP(B12,'비품현황표(전체)'!$A$1:$F$273,6,FALSE)) -> 유사모양 | H12: 2
A13: 12 | B13: XNORE10 | C13: Norepinephrine 10mg/10ml | D13: Norpin 10mg inj | E13: 10AMP/BOX | F13: 차광밀봉용기, 실온보관(1-30) | G13: =IF(VLOOKUP(B13,'비품현황표(전체)'!$A$1:$F$273,6,FALSE)=0,"",VLOOKUP(B13,'비품현황표(전체)'!$A$1:$F$273,6,FALSE)) | H13: 3
A14: 13 | B14: XMEXO | C14: Metoclopramide | D14: Macperan 10mg inj | E14: 50AMP/BOX | F14: 밀봉용기, 차광, 실온(1~30℃)보관 | G14: =IF(VLOOKUP(B14,'비품현황표(전체)'!$A$1:$F$273,6,FALSE)=0,"",VLOOKUP(B14,'비품현황표(전체)'!$A$1:$F$273,6,FALSE)) | H14: 2
A15: 14 | B15: XCPENIR | C15: Chlorpheniramine | D15: Peniramin 4mg/2ml inj | E15: 100AMP/BOX | F15: 밀봉용기 | G15: =IF(VLOOKUP(B15,'비품현황표(전체)'!$A$1:$F$273,6,FALSE)=0,"",VLOOKUP(B15,'비품현황표(전체)'!$A$1:$F$273,6,FALSE)) | H15: 2
A16: 15 | B16: XHPD | C16: Haloperidol 5mg/1ml | D16: Peridol 5mg inj | E16: 10AMP/BOX | F16: 밀봉용기, 차광하여 실온보관 | G16: =IF(VLOOKUP(B16,'비품현황표(전체)'!$A$1:$F$273,6,FALSE)=0,"",VLOOKUP(B16,'비품현황표(전체)'!$A$1:$F$273,6,FALSE)) -> 유사발음 | H16: 2
A17: 16 | B17: XTAZOC4W | C17: Tazoractam 4.5g inj | D17: Tazoractam 4.5g inj | F17: 밀봉용기, 실온(1-30℃) 보관 | H17: 2
A18: 17 | B18: XTRAM50 | C18: Tramadol 50mg/ml | D18: Tridol 50mg inj | E18: 50AMP/BOX | F18: 밀봉용기, 실온(1～30℃)보관 | G18: =IF(VLOOKUP(B18,'비품현황표(전체)'!$A$1:$F$273,6,FALSE)=0,"",VLOOKUP(B18,'비품현황표(전체)'!$A$1:$F$273,6,FALSE)) | H18: 5
D19: 보유비품약 품목수 | H19: 17

Sheet 101
A1: NO | B1: 약품코드 | C1: 일반명 | D1: 영문상품명 | E1: 규격 | F1: 보관조건 | G1: 혼돈주의약품 | H1: 25.06.11
A2: 1 | B2: ASP1PR | C2: Aspirin enteric coated 100mg tab | D2: Aspirin protect 100mg tab | E2: 1500TAB/BOX | F2: 기밀용기, 실온(25℃이하)보관 | G2: =IF(VLOOKUP(B2,'비품현황표(전체)'!$A$1:$F$273,6,FALSE)=0,"",VLOOKUP(B2,'비품현황표(전체)'!$A$1:$F$273,6,FALSE)) | H2: 3
A3: 2 | B3: IPRAT-RS | C3: Ipratropium bromide inh.soln 500mcg/2ml | D3: Atrovent UDV 2ml/Amp | E3: 20AMP/BOX*54 | F3: 밀봉용기, 실온보관 | G3: =IF(VLOOKUP(B3,'비품현황표(전체)'!$A$1:$F$273,6,FALSE)=0,"",VLOOKUP(B3,'비품현황표(전체)'!$A$1:$F$273,6,FALSE)) -> 유사모양 | H3: 3
A4: 3 | B4: XNICAR5 | D4: Binicapin 5mg/5ml inj | F4: 차광, 실온(1~30℃)보관 | G4: =IF(VLOOKUP(B4,'비품현황표(전체)'!$A$1:$F$273,6,FALSE)=0,"",VLOOKUP(B4,'비품현황표(전체)'!$A$1:$F$273,6,FALSE)) | H4: 2
A5: 4 | B5: XAMIOD | C5: Amiodarone 150mg | D5: Cordarone 150mg/3ml inj | E5: 6AMP/BOX | F5: 밀봉용기 | G5: =IF(VLOOKUP(B5,'비품현황표(전체)'!$A$1:$F$273,6,FALSE)=0,"",VLOOKUP(B5,'비품현황표(전체)'!$A$1:$F$273,6,FALSE)) | H5: 5
A6: 5 | B6: XPCMOL | C6: Propacetamol 1g | D6: Denogan 1g inj | E6: 10VIA/BOX | F6: 차광밀봉용기, 1~25℃보관 | G6: =IF(VLOOKUP(B6,'비품현황표(전체)'!$A$1:$F$273,6,FALSE)=0,"",VLOOKUP(B6,'비품현황표(전체)'!$A$1:$F$273,6,FALSE)) | H6: 3
A7: 6 | B7: XDILT | C7: Diltiazem 50mg inj | D7: Herben 50mg inj | E7: 10VIA/BOX | F7: 밀봉용기, 실온보존(1～30℃) | G7: =IF(VLOOKUP(B7,'비품현황표(전체)'!$A$1:$F$273,6,FALSE)=0,"",VLOOKUP(B7,'비품현황표(전체)'!$A$1:$F$273,6,FALSE)) | H7: 2
A8: 7 | B8: XKROL | C8: Ketorolac tromethamine 30mg | D8: Keromin 30mg Inj | E8: 50AMP/BOX | F8: 차광밀봉용기, 실온(1-30℃)보관 | G8: =IF(VLOOKUP(B8,'비품현황표(전체)'!$A$1:$F$273,6,FALSE)=0,"",VLOOKUP(B8,'비품현황표(전체)'!$A$1:$F$273,6,FALSE)) | H8: 3
A9: 8 | B9: XFURO | C9: Furosemide 20mg | D9: Lasix 20mg inj | E9: 50AMP/BOX | F9: 밀봉용기 실온보관 차광. | G9: =IF(VLOOKUP(B9,'비품현황표(전체)'!$A$1:$F$273,6,FALSE)=0,"",VLOOKUP(B9,'비품현황표(전체)'!$A$1:$F$273,6,FALSE)) -> 유사모양 | H9: 5
A10: 9 | B10: XMEXO | C10: Metoclopramide | D10: Macperan 10mg inj | E10: 50AMP/BOX | F10: 밀봉용기, 차광, 실온(1~30℃)보관 | G10: =IF(VLOOKUP(B10,'비품현황표(전체)'!$A$1:$F$273,6,FALSE)=0,"",VLOOKUP(B10,'비품현황표(전체)'!$A$1:$F$273,6,FALSE)) | H10: 3
A11: 10 | B11: XNORE10 | C11: Norepinephrine 10mg/10ml | D11: Norpin 10mg inj | E11: 10AMP/BOX | F11: 차광밀봉용기, 실온보관(1-30) | G11: =IF(VLOOKUP(B11,'비품현황표(전체)'!$A$1:$F$273,6,FALSE)=0,"",VLOOKUP(B11,'비품현황표(전체)'!$A$1:$F$273,6,FALSE)) | H11: 3
A12: 11 | B12: XCPENIR | C12: Chlorpheniramine | D12: Peniramin 4mg/2ml inj | E12: 100AMP/BOX | F12: 밀봉용기 | H12: 2
A13: 12 | B13: XHPD | C13: Haloperidol 5mg/1ml | D13: Peridol 5mg inj | E13: 10AMP/BOX | F13: 밀봉용기, 차광하여 실온보관 | G13: =IF(VLOOKUP(B13,'비품현황표(전체)'!$A$1:$F$273,6,FALSE)=0,"",VLOOKUP(B13,'비품현황표(전체)'!$A$1:$F$273,6,FALSE)) -> 유사발음 | H13: 1
A14: 13 | B14: CLOPID | C14: Clopidogrel 75mg | D14: Plavix 75mg tab | E14: 100TAB/BTL | F14: 기밀용기, 실온보관(1~30℃) | G14: =IF(VLOOKUP(B14,'비품현황표(전체)'!$A$1:$F$273,6,FALSE)=0,"",VLOOKUP(B14,'비품현황표(전체)'!$A$1:$F$273,6,FALSE)) -> 유사모양 | H14: 3
A15: 14 | B15: APH6ER1Y | C15: Acetaminophen ER 650mg | D15: Tramol ER 650mg tab | E15: 500TAB/BTL | F15: 밀폐용기 실온보관 | G15: =IF(VLOOKUP(B15,'비품현황표(전체)'!$A$1:$F$273,6,FALSE)=0,"",VLOOKUP(B15,'비품현황표(전체)'!$A$1:$F$273,6,FALSE)) | H15: 3
A16: 15 | B16: XTRAM50 | C16: Tramadol 50mg/ml | D16: Tridol 50mg inj | E16: 50AMP/BOX | F16: 밀봉용기, 실온(1～30℃)보관 | G16: =IF(VLOOKUP(B16,'비품현황표(전체)'!$A$1:$F$273,6,FALSE)=0,"",VLOOKUP(B16,'비품현황표(전체)'!$A$1:$F$273,6,FALSE)) | H16: 3
A17: 16 | B17: XHES6MPS5 | C17: Hydroxyethylstarch/Mg/K/Na | D17: Volulyte 6% 500ml inj | E17: 20bag/box | F17: 밀봉용기, 25℃ 이하 | G17: =IF(VLOOKUP(B17,'비품현황표(전체)'!$A$1:$F$273,6,FALSE)=0,"",VLOOKUP(B17,'비품현황표(전체)'!$A$1:$F$273,6,FALSE)) | H17: 2
D18: 보유비품약 품목수 | H18: 16

Sheet 102
A1: NO | B1: 약품코드 | C1: 일반명 | D1: 영문상품명 | E1: 규격 | F1: 보관조건 | G1: 혼돈주의약품 | H1: 26.05.04
A2: 1 | B2: XAPH1 | C2: Acetaminophen 1g/100ml | D2: Acetphen 1g/100ml premix inj | E2: 1bag | F2: 실온보관(1~30℃), 밀봉용기 | H2: 3
A3: 2 | B3: XNICAR5 | D3: Binicapin 5mg/5ml inj | F3: 차광, 실온(1~30℃)보관 | G3: =IF(VLOOKUP(B3,'비품현황표(전체)'!$A$1:$F$273,6,FALSE)=0,"",VLOOKUP(B3,'비품현황표(전체)'!$A$1:$F$273,6,FALSE)) | H3: 2
A4: 3 | B4: XPCMOL | C4: Propacetamol 1g | D4: Denogan 1g inj | E4: 10VIA/BOX | F4: 차광밀봉용기, 1~25℃보관 | G4: =IF(VLOOKUP(B4,'비품현황표(전체)'!$A$1:$F$273,6,FALSE)=0,"",VLOOKUP(B4,'비품현황표(전체)'!$A$1:$F$273,6,FALSE)) | H4: 3
A5: 4 | B5: XKROL | C5: Ketorolac tromethamine 30mg | D5: Keromin 30mg Inj | E5: 50AMP/BOX | F5: 차광밀봉용기, 실온(1-30℃)보관 | G5: =IF(VLOOKUP(B5,'비품현황표(전체)'!$A$1:$F$273,6,FALSE)=0,"",VLOOKUP(B5,'비품현황표(전체)'!$A$1:$F$273,6,FALSE)) | H5: 3
A6: 5 | B6: XFURO | C6: Furosemide 20mg | D6: Lasix 20mg inj | E6: 50AMP/BOX | F6: 밀봉용기 실온보관 차광. | G6: =IF(VLOOKUP(B6,'비품현황표(전체)'!$A$1:$F$273,6,FALSE)=0,"",VLOOKUP(B6,'비품현황표(전체)'!$A$1:$F$273,6,FALSE)) -> 유사모양 | H6: 3
A7: 6 | B7: XMEXO | C7: Metoclopramide | D7: Macperan 10mg inj | E7: 50AMP/BOX | F7: 밀봉용기, 차광, 실온(1~30℃)보관 | G7: =IF(VLOOKUP(B7,'비품현황표(전체)'!$A$1:$F$273,6,FALSE)=0,"",VLOOKUP(B7,'비품현황표(전체)'!$A$1:$F$273,6,FALSE)) | H7: 2
A8: 7 | B8: XCPENIR | C8: Chlorpheniramine | D8: Peniramin 4mg/2ml inj | E8: 100AMP/BOX | F8: 밀봉용기 | G8: =IF(VLOOKUP(B8,'비품현황표(전체)'!$A$1:$F$273,6,FALSE)=0,"",VLOOKUP(B8,'비품현황표(전체)'!$A$1:$F$273,6,FALSE)) | H8: 2
A9: 8 | B9: XHPD | C9: Haloperidol 5mg/1ml | D9: Peridol 5mg inj | E9: 10AMP/BOX | F9: 밀봉용기, 차광하여 실온보관 | G9: =IF(VLOOKUP(B9,'비품현황표(전체)'!$A$1:$F$273,6,FALSE)=0,"",VLOOKUP(B9,'비품현황표(전체)'!$A$1:$F$273,6,FALSE)) -> 유사발음 | H9: 2
A10: 9 | B10: XMPD1W | D10: Predisol 125mg inj | F10: 실온보관,밀봉용기 | H10: 1
A11: 10 | B11: XAMIOD | C11: Amiodarone 150mg | D11: Cordarone 150mg/3ml inj | E11: 6AMP/BOX | F11: 밀봉용기 | G11: =IF(VLOOKUP(B12,'비품현황표(전체)'!$A$1:$F$273,6,FALSE)=0,"",VLOOKUP(B12,'비품현황표(전체)'!$A$1:$F$273,6,FALSE)) | H11: 4
A12: 11 | B12: XTRAM50 | C12: Tramadol 50mg/ml | D12: Tridol 50mg inj | E12: 50AMP/BOX | F12: 밀봉용기, 실온(1～30℃)보관 | H12: 3
D13: 보유비품약 품목수 | H13: 11

Sheet 111
A1: NO | B1: 약품코드 | C1: 일반명 | D1: 영문상품명 | E1: 규격 | F1: 보관조건 | G1: 혼돈주의약품 | H1: 24.11.07
A2: 1 | B2: XAPH1 | C2: Acetaminophen 1g/100ml | D2: Acetphen 1g/100ml premix inj | E2: 1bag | F2: 실온보관(1~30℃), 밀봉용기 | H2: 1
A3: 2 | B3: XNICAR5 | C3: nicardipine hydrochloride | D3: Binicapin 5mg/5ml inj | E3: 25AMP/BOX | F3: 차광, 실온(1~30℃)보관 | H3: 1
A4: 3 | B4: XPCMOL | C4: Propacetamol 1g | D4: Denogan 1g inj | E4: 10VIA/BOX | F4: =VLOOKUP(B4,'비품현황표(전체)'!$A6:$AT275,5,FALSE) -> 차광밀봉용기, 1~25℃보관 | G4: =IF(VLOOKUP(B4,'비품현황표(전체)'!$A$1:$F$273,6,FALSE)=0,"",VLOOKUP(B4,'비품현황표(전체)'!$A$1:$F$273,6,FALSE)) | H4: 6
A5: 4 | B5: XDICLOF | C5: diclofenac-β-dimethyl-aminoethanol 90mg/2ml | D5: Dibeta-C 90mg/2ml inj | E5: 50AMP/BOX | F5: =VLOOKUP(B5,'비품현황표(전체)'!$A7:$AT276,5,FALSE) -> 차광밀봉용기, 실온(1~30℃)보관 | G5: =IF(VLOOKUP(B5,'비품현황표(전체)'!$A$1:$F$273,6,FALSE)=0,"",VLOOKUP(B5,'비품현황표(전체)'!$A$1:$F$273,6,FALSE)) | H5: 1
A6: 5 | B6: XKROL | C6: Ketorolac tromethamine 30mg | D6: Keromin 30mg Inj | E6: 50AMP/BOX | F6: =VLOOKUP(B6,'비품현황표(전체)'!$A11:$AT278,5,FALSE) -> 차광밀봉용기, 실온(1-30℃)보관 | G6: =IF(VLOOKUP(B6,'비품현황표(전체)'!$A$1:$F$273,6,FALSE)=0,"",VLOOKUP(B6,'비품현황표(전체)'!$A$1:$F$273,6,FALSE)) | H6: 3
A7: 6 | B7: XFURO | C7: Furosemide 20mg | D7: Lasix 20mg inj | E7: 50AMP/BOX | F7: 밀봉용기 실온보관 차광. | G7: 유사모양 | H7: 1
A8: 7 | B8: XMEXO | C8: Metoclopramide | D8: Macperan 10mg inj | E8: 50AMP/BOX | F8: =VLOOKUP(B8,'비품현황표(전체)'!$A13:$AT279,5,FALSE) -> 밀봉용기, 차광, 실온(1~30℃)보관 | G8: =IF(VLOOKUP(B8,'비품현황표(전체)'!$A$1:$F$273,6,FALSE)=0,"",VLOOKUP(B8,'비품현황표(전체)'!$A$1:$F$273,6,FALSE)) | H8: 3
A9: 8 | B9: MYP-T | C9: Tropicamide/Phenylephrine oph sol | D9: Mydrin-P oph sol | E9: 10ML/BTL | F9: =VLOOKUP(B9,'비품현황표(전체)'!$A13:$AT280,5,FALSE) -> 기밀용기, 실온보관(1~30℃) | G9: =IF(VLOOKUP(B9,'비품현황표(전체)'!$A$1:$F$273,6,FALSE)=0,"",VLOOKUP(B9,'비품현황표(전체)'!$A$1:$F$273,6,FALSE)) | H9: 1
A10: 9 | B10: XCPENIR | C10: Chlorpheniramine | D10: Peniramin 4mg/2ml inj | E10: 100AMP/BOX | F10: 밀봉용기 | H10: 1
A11: 10 | B11: XTRAM50 | C11: Tramadol 50mg/ml | D11: Tridol 50mg inj | E11: 50AMP/BOX | F11: =VLOOKUP(B11,'비품현황표(전체)'!$A13:$AT282,5,FALSE) -> 밀봉용기, 실온(1～30℃)보관 | G11: =IF(VLOOKUP(B11,'비품현황표(전체)'!$A$1:$F$273,6,FALSE)=0,"",VLOOKUP(B11,'비품현황표(전체)'!$A$1:$F$273,6,FALSE)) | H11: 2
D12: 보유비품종류 | H12: 10

Sheet 112
A1: NO | B1: 약품코드 | C1: 일반명 | D1: 영문상품명 | E1: 보관조건 | F1: 혼돈주의약품 | G1: 23.02.28
A2: 1 | B2: XNICAR5 | D2: Binicapin 5mg/5ml inj | E2: 차광, 실온(1~30℃)보관 | F2: =IF(VLOOKUP(B2,'비품현황표(전체)'!$A$1:$F$273,6,FALSE)=0,"",VLOOKUP(B2,'비품현황표(전체)'!$A$1:$F$273,6,FALSE)) | G2: 2
A3: 2 | B3: XPCMOL | C3: Propacetamol 1g | D3: Denogan 1g inj | E3: 차광밀봉용기, 1~25℃보관 | F3: =IF(VLOOKUP(B3,'비품현황표(전체)'!$A$1:$F$273,6,FALSE)=0,"",VLOOKUP(B3,'비품현황표(전체)'!$A$1:$F$273,6,FALSE)) | G3: 5
A4: 3 | B4: BISA1-P | D4: Dulcolax Supp | E4: 기밀용기, 실온(1~30℃)보관 | F4: =IF(VLOOKUP(B4,'비품현황표(전체)'!$A$1:$F$273,6,FALSE)=0,"",VLOOKUP(B4,'비품현황표(전체)'!$A$1:$F$273,6,FALSE)) | G4: 2
A5: 4 | B5: SMECD-K | D5: fotaGEL susp 20ml/pkg | E5: 기밀용기, 실온보관(1-30℃) | F5: =IF(VLOOKUP(B5,'비품현황표(전체)'!$A$1:$F$273,6,FALSE)=0,"",VLOOKUP(B5,'비품현황표(전체)'!$A$1:$F$273,6,FALSE)) | G5: 2
A6: 5 | B6: XKROL | C6: Ketorolac tromethamine 30mg | D6: Keromin 30mg Inj | E6: 차광밀봉용기, 실온(1-30℃)보관 | F6: =IF(VLOOKUP(B6,'비품현황표(전체)'!$A$1:$F$273,6,FALSE)=0,"",VLOOKUP(B6,'비품현황표(전체)'!$A$1:$F$273,6,FALSE)) | G6: 5
A7: 6 | B7: XMEXO | C7: Metoclopramide | D7: Macperan 10mg inj | E7: 밀봉용기, 차광, 실온(1~30℃)보관 | F7: =IF(VLOOKUP(B7,'비품현황표(전체)'!$A$1:$F$273,6,FALSE)=0,"",VLOOKUP(B7,'비품현황표(전체)'!$A$1:$F$273,6,FALSE)) | G7: 5
A8: 7 | B8: XGPYRO | D8: Mobinul 0.2mg/1ml inj | E8: 밀봉용기, 실온(1~30℃)보관 | F8: =IF(VLOOKUP(B8,'비품현황표(전체)'!$A$1:$F$273,6,FALSE)=0,"",VLOOKUP(B8,'비품현황표(전체)'!$A$1:$F$273,6,FALSE)) | G8: 2
A9: 8 | B9: XCPENIR | C9: Chlorpheniramine | D9: Peniramin 4mg/2ml inj | E9: 밀봉용기 | F9: =IF(VLOOKUP(B9,'비품현황표(전체)'!$A$1:$F$273,6,FALSE)=0,"",VLOOKUP(B9,'비품현황표(전체)'!$A$1:$F$273,6,FALSE)) | G9: 3
A10: 9 | B10: XHPD | C10: Haloperidol 5mg/1ml | D10: Peridol 5mg inj | E10: 밀봉용기, 차광하여 실온보관 | F10: =IF(VLOOKUP(B10,'비품현황표(전체)'!$A$1:$F$273,6,FALSE)=0,"",VLOOKUP(B10,'비품현황표(전체)'!$A$1:$F$273,6,FALSE)) -> 유사발음 | G10: 5
A11: 10 | B11: XFURO | C11: Furosemide 20mg | D11: Lasix 20mg inj | E11: 밀봉용기 실온보관 차광. | F11: 유사모양 | G11: 2
A12: 11 | B12: APH6ER1Y | C12: Acetaminophen ER 650mg | D12: Tramol ER 650mg tab | E12: 밀폐용기 실온보관 | F12: =IF(VLOOKUP(B12,'비품현황표(전체)'!$A$1:$F$273,6,FALSE)=0,"",VLOOKUP(B12,'비품현황표(전체)'!$A$1:$F$273,6,FALSE)) | G12: 3
A13: 12 | B13: XTRAM50 | C13: Tramadol 50mg/ml | D13: Tridol 50mg inj | E13: 밀봉용기, 실온(1～30℃)보관 | F13: =IF(VLOOKUP(B13,'비품현황표(전체)'!$A$1:$F$273,6,FALSE)=0,"",VLOOKUP(B13,'비품현황표(전체)'!$A$1:$F$273,6,FALSE)) | G13: 5
D14: 보유비품약 품목수 | G14: 12

Sheet 121
A1: NO | B1: 약품코드 | C1: 일반명 | D1: 영문상품명 | E1: 규격 | F1: 보관조건 | G1: 혼돈주의약품 | H1: 121W
A2: 1 | B2: XHPD | C2: Haloperidol 5mg/1ml | D2: Peridol 5mg inj | E2: 10AMP/BOX | F2: =VLOOKUP(B2,'비품현황표(전체)'!$A1:$AT274,5,FALSE) -> 밀봉용기, 차광하여 실온보관 | G2: =IF(VLOOKUP(B2,'비품현황표(전체)'!$A$1:$F$273,6,FALSE)=0,"",VLOOKUP(B2,'비품현황표(전체)'!$A$1:$F$273,6,FALSE)) -> 유사발음 | H2: 5
D3: 보유비품종류 | H3: 1

Sheet SICU
A1: NO | B1: 약품코드 | C1: 일반명 | D1: 영문상품명 | E1: 규격 | F1: 보관조건 | G1: 혼돈주의약품 | H1: 25.07.28
A2: 1 | B2: XAPH1 | C2: Acetaminophen 1g/100ml | D2: Acetphen 1g/100ml premix inj | E2: 1bag | F2: 실온보관(1~30℃), 밀봉용기 | G2: =IF(VLOOKUP(B2,'비품현황표(전체)'!$A$1:$F$273,6,FALSE)=0,"",VLOOKUP(B2,'비품현황표(전체)'!$A$1:$F$273,6,FALSE)) | H2: 3
A3: 2 | B3: XNICAR5 | D3: Binicapin 5mg/5ml inj | F3: 차광, 실온(1~30℃)보관 | G3: =IF(VLOOKUP(B3,'비품현황표(전체)'!$A$1:$F$273,6,FALSE)=0,"",VLOOKUP(B3,'비품현황표(전체)'!$A$1:$F$273,6,FALSE)) | H3: 10
A4: 3 | B4: XEMOL1 | C4: Esmolol HCl 100mg | D4: Brevibloc 100mg inj | E4: 20VIA/BOX | F4: 실온보관 | G4: =IF(VLOOKUP(B4,'비품현황표(전체)'!$A$1:$F$273,6,FALSE)=0,"",VLOOKUP(B4,'비품현황표(전체)'!$A$1:$F$273,6,FALSE)) | H4: 2
A5: 4 | B5: XCAGL | C5: Calcium gluconate 9.29mEq/amp | D5: Calcium gluconate 2g inj | E5: 50AMP/BOX | F5: 밀봉용기, 실온(1 - 30℃)보관 | G5: =IF(VLOOKUP(B5,'비품현황표(전체)'!$A$1:$F$273,6,FALSE)=0,"",VLOOKUP(B5,'비품현황표(전체)'!$A$1:$F$273,6,FALSE)) | H5: 3
A6: 5 | B6: XAMIOD | C6: Amiodarone 150mg | D6: Cordarone 150mg/3ml inj | E6: 6AMP/BOX | F6: 밀봉용기 | H6: 5
A7: 6 | B7: XPCMOL | C7: Propacetamol 1g | D7: Denogan 1g inj | E7: 10VIA/BOX | F7: 차광밀봉용기, 1~25℃보관 | G7: =IF(VLOOKUP(B7,'비품현황표(전체)'!$A$1:$F$273,6,FALSE)=0,"",VLOOKUP(B7,'비품현황표(전체)'!$A$1:$F$273,6,FALSE)) | H7: 5
A8: 7 | B8: XDXM | C8: Dexamethasone 5mg | D8: Dexamethasone 5mg inj | E8: 50AMP/BOX | F8: 차광한 밀봉용기, 실온(1 ~ 30℃) 보관 | G8: =IF(VLOOKUP(B8,'비품현황표(전체)'!$A$1:$F$273,6,FALSE)=0,"",VLOOKUP(B8,'비품현황표(전체)'!$A$1:$F$273,6,FALSE)) -> 유사발음 | H8: 2
A9: 8 | B9: XDGX | C9: Digoxin 0.25mg/1ml | D9: Digoxin 0.25mg inj | E9: 10AMP/BOX | F9: 밀봉용기 | G9: =IF(VLOOKUP(B9,'비품현황표(전체)'!$A$1:$F$273,6,FALSE)=0,"",VLOOKUP(B9,'비품현황표(전체)'!$A$1:$F$273,6,FALSE)) | H9: 1
A10: 9 | B10: XDOB5D2 | C10: Dobutamine/D5W 500mg/250ml bag | D10: DOBUTamine/D5W 500mg/250ml bag | E10: 20BAG/BOX | F10: 밀봉용기, 25℃이하에서 보관 | G10: =IF(VLOOKUP(B10,'비품현황표(전체)'!$A$1:$F$273,6,FALSE)=0,"",VLOOKUP(B10,'비품현황표(전체)'!$A$1:$F$273,6,FALSE)) -> 유사발음 | H10: 1
A11: 10 | B11: XDOPA4D2 | C11: Dopamine/D5W 400mg/200ml bag | D11: DOPamine/D5W 400mg/200ml bag CJ | E11: 30BAG/BOX | F11: 밀봉용기, 실온(1-30℃)보관 | G11: =IF(VLOOKUP(B11,'비품현황표(전체)'!$A$1:$F$273,6,FALSE)=0,"",VLOOKUP(B11,'비품현황표(전체)'!$A$1:$F$273,6,FALSE)) -> 유사발음 | H11: 3
A12: 11 | B12: XDOB250 | C12: Dobutamine 250mg Inj | D12: Doburan 250mg/5ml Inj | E12: 10 AMP/BOX | F12: 밀봉용기, 상온(15 ~ 25℃)보관 | H12: 4
A13: 12 | B13: XEPIN | C13: Epinephrine HCl 1mg | D13: Epinephrine 1mg/1ml inj | E13: 50AMP/BOX | F13: 차광밀봉용기, 25℃이하 보관, 냉장보관하지 말 것. | G13: =IF(VLOOKUP(B13,'비품현황표(전체)'!$A$1:$F$273,6,FALSE)=0,"",VLOOKUP(B13,'비품현황표(전체)'!$A$1:$F$273,6,FALSE)) -> 유사발음 | H13: 20
A14: 13 | B14: XROCU50 | C14: Esmeron 50mg/5ml inj | D14: Esmeron 50mg/5ml inj | E14: 10 VIAL/BOX | F14: 밀봉용기, 2-8℃보관 | G14: =IF(VLOOKUP(B14,'비품현황표(전체)'!$A$1:$F$273,6,FALSE)=0,"",VLOOKUP(B14,'비품현황표(전체)'!$A$1:$F$273,6,FALSE)) -> 고위험의약품 | H14: 1
A15: 14 | B15: MUPIR1Y-O | D15: Esroban 10g oint | F15: 기밀용기, 실온(1~30℃)보관 | H15: 1
A16: 15 | B16: XNFMOS50 | C16: Nafamostat 50mg | D16: Futhan 50mg inj | E16: 10VIA/BOX | F16: 차광, 밀봉용기, 실온(1-30℃)보관 | G16: =IF(VLOOKUP(B16,'비품현황표(전체)'!$A$1:$F$273,6,FALSE)=0,"",VLOOKUP(B16,'비품현황표(전체)'!$A$1:$F$273,6,FALSE)) | H16: 4
A17: 16 | B17: XHEPAR1 | C17: Heparin sodium 20000IU/20ml | D17: Heparin sod. 20000IU/20ml inj 중외 | E17: 10VIA/BOX | F17: 차광한 밀봉용기 | G17: =IF(VLOOKUP(B17,'비품현황표(전체)'!$A$1:$F$273,6,FALSE)=0,"",VLOOKUP(B17,'비품현황표(전체)'!$A$1:$F$273,6,FALSE)) -> 고위험의약품 | H17: 2
A18: 17 | B18: XHEP100PM | C18: Heparin sodium 100IU/ml | D18: Heparin sodium inj 100IU/ml | E18: 10VIAL/BOX | F18: 차광밀봉용기, 실온(1~30℃)보관 | G18: =IF(VLOOKUP(B18,'비품현황표(전체)'!$A$1:$F$273,6,FALSE)=0,"",VLOOKUP(B18,'비품현황표(전체)'!$A$1:$F$273,6,FALSE)) -> 고위험의약품 | H18: 2
A19: 18 | B19: XHEPAR15 | D19: HEPARIN sod. 5000iu/5ml inj | F19: 차광한 밀봉용기 | G19: 고위험의약품 | H19: 2
A20: 19 | B20: XDILT | C20: Diltiazem 50mg inj | D20: Herben 50mg inj | E20: 10VIA/BOX | F20: 밀봉용기, 실온보존(1～30℃) | G20: =IF(VLOOKUP(B20,'비품현황표(전체)'!$A$1:$F$273,6,FALSE)=0,"",VLOOKUP(B20,'비품현황표(전체)'!$A$1:$F$273,6,FALSE)) | H20: 2
A21: 20 | B21: XKROL | C21: Ketorolac tromethamine 30mg | D21: Keromin 30mg Inj | E21: 50AMP/BOX | F21: 차광밀봉용기, 실온(1-30℃)보관 | G21: =IF(VLOOKUP(B21,'비품현황표(전체)'!$A$1:$F$273,6,FALSE)=0,"",VLOOKUP(B21,'비품현황표(전체)'!$A$1:$F$273,6,FALSE)) | H21: 5
A22: 21 | B22: XLABETA20 | C22: Labetalol HCl 20mg inj | D22: Labesin 20mg/4ml inj | E22: 50AMP/BOX | F22: 차광밀봉용기, 실온보관 | G22: =IF(VLOOKUP(B22,'비품현황표(전체)'!$A$1:$F$273,6,FALSE)=0,"",VLOOKUP(B22,'비품현황표(전체)'!$A$1:$F$273,6,FALSE)) | H22: 5
A23: 22 | B23: HCORT1-LT | D23: Lacticare HC lotion1% 118g | F23: 기밀용기, 실온(1~30℃)보관 | H23: 1
A24: 23 | B24: XFURO | C24: Furosemide 20mg | D24: Lasix 20mg inj | E24: 50AMP/BOX | F24: 밀봉용기 실온보관 차광. | G24: =IF(VLOOKUP(B24,'비품현황표(전체)'!$A$1:$F$273,6,FALSE)=0,"",VLOOKUP(B24,'비품현황표(전체)'!$A$1:$F$273,6,FALSE)) -> 유사모양 | H24: 5
A25: 24 | B25: XMEXO | C25: Metoclopramide | D25: Macperan 10mg inj | E25: 50AMP/BOX | F25: 밀봉용기, 차광, 실온(1~30℃)보관 | G25: =IF(VLOOKUP(B25,'비품현황표(전체)'!$A$1:$F$273,6,FALSE)=0,"",VLOOKUP(B25,'비품현황표(전체)'!$A$1:$F$273,6,FALSE)) | H25: 5
A26: 25 | B26: XMGSF10 | C26: MgSO4 10% 20ml | D26: Magnesium sulfate 10% 20ml inj | E26: 50AMP/BOX | F26: 밀봉용기, 실온(1∼30℃)보관 | G26: =IF(VLOOKUP(B26,'비품현황표(전체)'!$A$1:$F$273,6,FALSE)=0,"",VLOOKUP(B26,'비품현황표(전체)'!$A$1:$F$273,6,FALSE)) | H26: 3
A27: 26 | B27: X20M1X | C27: Mannitol(D-) 20% 100ml | D27: Mannitol 20% 100ml bag대한 | E27: 50BAG/BOX | F27: 밀봉용기 | H27: 3
A28: 27 | B28: XNA40 | C28: NaCl 40mEq/20ml plastic amp | D28: NaCl 40mEq/20ml | E28: 50AMP/BOX | F28: 밀봉용기, 실온(1~30℃)보관 | G28: =IF(VLOOKUP(B28,'비품현황표(전체)'!$A$1:$F$273,6,FALSE)=0,"",VLOOKUP(B28,'비품현황표(전체)'!$A$1:$F$273,6,FALSE)) | H28: 5
A29: 28 | B29: XNICAR2 | C29: nicardipine hydrochloride 20㎎/20㎖ | D29: Nicardipine inj (HUONS) | F29: 차광하여 밀봉용기에 보관, 실온(1~30℃)보관 | G29: =IF(VLOOKUP(B29,'비품현황표(전체)'!$A$1:$F$273,6,FALSE)=0,"",VLOOKUP(B29,'비품현황표(전체)'!$A$1:$F$273,6,FALSE)) | H29: 10
A30: 29 | B30: XNITR10F | C30: Nitroglycerin 10mg | D30: Nitrolingual 10mg inj | E30: 10 AMP/BOX | F30: 밀봉용기, 실온보관 | G30: =IF(VLOOKUP(B30,'비품현황표(전체)'!$A$1:$F$273,6,FALSE)=0,"",VLOOKUP(B30,'비품현황표(전체)'!$A$1:$F$273,6,FALSE)) -> 유사모양 | H30: 5
A31: 30 | B31: XNORE10 | C31: Norepinephrine 10mg/10ml | D31: Norpin 10mg inj | E31: 10AMP/BOX | F31: 차광밀봉용기, 실온보관(1-30) | G31: =IF(VLOOKUP(B31,'비품현황표(전체)'!$A$1:$F$273,6,FALSE)=0,"",VLOOKUP(B31,'비품현황표(전체)'!$A$1:$F$273,6,FALSE)) | H31: 5
A32: 31 | B32: XNICAR | C32: Nicardipine 10mg | D32: Perdipine 10mg inj | E32: 10AMP/BOX | F32: 차광,실온보관 | G32: =IF(VLOOKUP(B32,'비품현황표(전체)'!$A$1:$F$273,6,FALSE)=0,"",VLOOKUP(B32,'비품현황표(전체)'!$A$1:$F$273,6,FALSE)) -> 유사모양 | H32: 10
A33: 32 | B33: XHPD | C33: Haloperidol 5mg/1ml | D33: Peridol 5mg inj | E33: 10AMP/BOX | F33: 밀봉용기, 차광하여 실온보관 | G33: =IF(VLOOKUP(B33,'비품현황표(전체)'!$A$1:$F$273,6,FALSE)=0,"",VLOOKUP(B33,'비품현황표(전체)'!$A$1:$F$273,6,FALSE)) -> 유사발음 | H33: 3
A34: 33 | B34: XKPHMB | C34: Potassium phosphate monobasic 20ml inj | D34: Phosten 20ml inj | E34: 50AMP/BOX | F34: 밀봉용기, 15-30℃에서 보관 | G34: =IF(VLOOKUP(B34,'비품현황표(전체)'!$A$1:$F$273,6,FALSE)=0,"",VLOOKUP(B34,'비품현황표(전체)'!$A$1:$F$273,6,FALSE)) | H34: 3
A35: 34 | B35: XPROT | C35: Protamine 50mg | D35: Protamine sulfate 50mg inj | E35: 5AMP/BOX | F35: 밀봉용기, 실온보존 | G35: =IF(VLOOKUP(B35,'비품현황표(전체)'!$A$1:$F$273,6,FALSE)=0,"",VLOOKUP(B35,'비품현황표(전체)'!$A$1:$F$273,6,FALSE)) | H35: 2
A36: 35 | B36: XNB84 | C36: NaHCO3 8.4% 20ml amp | D36: Sod.bicarbonate 8.4% 20ml inj | E36: 50AMP/BOX | F36: 밀봉용기, 실온보관(1~30℃) | G36: =IF(VLOOKUP(B36,'비품현황표(전체)'!$A$1:$F$273,6,FALSE)=0,"",VLOOKUP(B36,'비품현황표(전체)'!$A$1:$F$273,6,FALSE)) | H36: 30
A37: 36 | B37: XTRAM50 | C37: Tramadol 50mg/ml | D37: Tridol 50mg inj | E37: 50AMP/BOX | F37: 밀봉용기, 실온(1～30℃)보관 | G37: =IF(VLOOKUP(B37,'비품현황표(전체)'!$A$1:$F$273,6,FALSE)=0,"",VLOOKUP(B37,'비품현황표(전체)'!$A$1:$F$273,6,FALSE)) | H37: 5
A38: 37 | B38: XDOPA4 | C38: Dopamine HCl 400mg | D38: Tropin 400mg inj | E38: 5AMP/BOX | F38: 차광한 밀봉용기 | G38: =IF(VLOOKUP(B38,'비품현황표(전체)'!$A$1:$F$273,6,FALSE)=0,"",VLOOKUP(B38,'비품현황표(전체)'!$A$1:$F$273,6,FALSE)) | H38: 2
A39: 38 | B39: XADH | C39: Vasopressin 20u | D39: Vasopressin 20u inj | E39: 10AMP/BOX | F39: 동결을 피하여 냉소보존(15℃이하), 밀봉용기 | G39: =IF(VLOOKUP(B39,'비품현황표(전체)'!$A$1:$F$273,6,FALSE)=0,"",VLOOKUP(B39,'비품현황표(전체)'!$A$1:$F$273,6,FALSE)) | H39: 5
A40: 39 | B40: XVECUR10Y | C40: Vecuronium bromide 10mg | D40: Vecaron 10mg inj | E40: 10VIAL/BOX | F40: 밀봉용기 25℃ 이하에서 보관 | G40: =IF(VLOOKUP(B40,'비품현황표(전체)'!$A$1:$F$273,6,FALSE)=0,"",VLOOKUP(B40,'비품현황표(전체)'!$A$1:$F$273,6,FALSE)) | H40: 5
...

Sheet MICU
A1: NO | B1: 약품코드 | C1: 일반명 | D1: 영문상품명 | E1: 규격 | F1: 보관조건 | G1: 혼돈주의약품 | H1: 26.05.22
A2: 1 | B2: XAPH1 | C2: Acetaminophen 1g/100ml | D2: Acetphen 1g/100ml premix inj | E2: 1bag | F2: 실온보관(1~30℃), 밀봉용기 | G2: =IF(VLOOKUP(B2,'비품현황표(전체)'!$A$1:$F$273,6,FALSE)=0,"",VLOOKUP(B2,'비품현황표(전체)'!$A$1:$F$273,6,FALSE)) | H2: 3
A3: 2 | B3: XADENO6 | C3: Adenosine 6mg | D3: Adenocor 6mg/2ml inj | E3: 6VIAL/BOX | F3: 밀봉용기 | G3: =IF(VLOOKUP(B3,'비품현황표(전체)'!$A$1:$F$273,6,FALSE)=0,"",VLOOKUP(B3,'비품현황표(전체)'!$A$1:$F$273,6,FALSE)) | H3: 5
A4: 3 | B4: XNICAR5 | D4: Binicapin 5mg/5ml inj | F4: 차광, 실온(1~30℃)보관 | G4: =IF(VLOOKUP(B4,'비품현황표(전체)'!$A$1:$F$273,6,FALSE)=0,"",VLOOKUP(B4,'비품현황표(전체)'!$A$1:$F$273,6,FALSE)) | H4: 2
A5: 4 | B5: XEMOL1 | C5: Esmolol HCl 100mg | D5: Brevibloc 100mg inj | E5: 20VIA/BOX | F5: 실온보관 | G5: =IF(VLOOKUP(B5,'비품현황표(전체)'!$A$1:$F$273,6,FALSE)=0,"",VLOOKUP(B5,'비품현황표(전체)'!$A$1:$F$273,6,FALSE)) | H5: 2
A6: 5 | B6: XCAGL | C6: Calcium gluconate 9.29mEq/amp | D6: Calcium gluconate 2g inj | E6: 50AMP/BOX | F6: 밀봉용기, 실온(1 - 30℃)보관 | G6: =IF(VLOOKUP(B6,'비품현황표(전체)'!$A$1:$F$273,6,FALSE)=0,"",VLOOKUP(B6,'비품현황표(전체)'!$A$1:$F$273,6,FALSE)) | H6: 5
A7: 6 | B7: XAMIOD | C7: Amiodarone 150mg | D7: Cordarone 150mg/3ml inj | E7: 6AMP/BOX | F7: 밀봉용기 | G7: =IF(VLOOKUP(B7,'비품현황표(전체)'!$A$1:$F$273,6,FALSE)=0,"",VLOOKUP(B7,'비품현황표(전체)'!$A$1:$F$273,6,FALSE)) | H7: 4
A8: 7 | B8: XPCMOL | C8: Propacetamol 1g | D8: Denogan 1g inj | E8: 10VIA/BOX | F8: 차광밀봉용기, 1~25℃보관 | G8: =IF(VLOOKUP(B8,'비품현황표(전체)'!$A$1:$F$273,6,FALSE)=0,"",VLOOKUP(B8,'비품현황표(전체)'!$A$1:$F$273,6,FALSE)) | H8: 5
A9: 8 | B9: XDOB250 | C9: Dobutamine 250mg Inj | D9: Doburan 250mg/5ml Inj | E9: 10 AMP/BOX | F9: 밀봉용기, 상온(15 ~ 25℃)보관 | G9: =IF(VLOOKUP(B9,'비품현황표(전체)'!$A$1:$F$273,6,FALSE)=0,"",VLOOKUP(B9,'비품현황표(전체)'!$A$1:$F$273,6,FALSE)) | H9: 8
A10: 9 | B10: XDOB5D2 | C10: Dobutamine/D5W 500mg/250ml bag | D10: DOBUTamine/D5W 500mg/250ml bag | E10: 20BAG/BOX | F10: 밀봉용기, 25℃이하에서 보관 | G10: =IF(VLOOKUP(B10,'비품현황표(전체)'!$A$1:$F$273,6,FALSE)=0,"",VLOOKUP(B10,'비품현황표(전체)'!$A$1:$F$273,6,FALSE)) -> 유사발음 | H10: 2
A11: 10 | B11: XDOPA4D2 | C11: Dopamine/D5W 400mg/200ml bag | D11: DOPamine/D5W 400mg/200ml bag CJ | E11: 30BAG/BOX | F11: 밀봉용기, 실온(1-30℃)보관 | G11: =IF(VLOOKUP(B11,'비품현황표(전체)'!$A$1:$F$273,6,FALSE)=0,"",VLOOKUP(B11,'비품현황표(전체)'!$A$1:$F$273,6,FALSE)) -> 유사발음 | H11: 3
A12: 11 | B12: XEPIN | C12: Epinephrine HCl 1mg | D12: Epinephrine 1mg/1ml inj | E12: 50AMP/BOX | F12: 차광밀봉용기, 25℃이하 보관, 냉장보관하지 말 것. | G12: =IF(VLOOKUP(B12,'비품현황표(전체)'!$A$1:$F$273,6,FALSE)=0,"",VLOOKUP(B12,'비품현황표(전체)'!$A$1:$F$273,6,FALSE)) -> 유사발음 | H12: 20
A13: 12 | B13: XROCU50 | C13: Esmeron 50mg/5ml inj | D13: Esmeron 50mg/5ml inj | E13: 10 VIAL/BOX | F13: 밀봉용기, 2-8℃보관 | G13: =IF(VLOOKUP(B13,'비품현황표(전체)'!$A$1:$F$273,6,FALSE)=0,"",VLOOKUP(B13,'비품현황표(전체)'!$A$1:$F$273,6,FALSE)) -> 고위험의약품 | H13: 1
A14: 13 | B14: XFLUMA3 | C14: Flumazenil 0.3mg | D14: Flunil 0.3mg/3ml inj | E14: 5AMP/BOX | F14: 밀봉용기, 30℃이하 보관 | G14: =IF(VLOOKUP(B14,'비품현황표(전체)'!$A$1:$F$273,6,FALSE)=0,"",VLOOKUP(B14,'비품현황표(전체)'!$A$1:$F$273,6,FALSE)) | H14: 2
A15: 14 | B15: XNFMOS50 | C15: Nafamostat 50mg | D15: Futhan 50mg inj | E15: 10VIA/BOX | F15: 차광, 밀봉용기, 실온(1-30℃)보관 | G15: =IF(VLOOKUP(B15,'비품현황표(전체)'!$A$1:$F$273,6,FALSE)=0,"",VLOOKUP(B15,'비품현황표(전체)'!$A$1:$F$273,6,FALSE)) | H15: 4
A16: 15 | B16: XHEPAR5 | C16: Heparin sodium 25000u | D16: Heparin sod. 25000IU/5ml inj | E16: 10VIA/BOX | F16: 밀봉용기, 실온보존 | G16: =IF(VLOOKUP(B16,'비품현황표(전체)'!$A$1:$F$273,6,FALSE)=0,"",VLOOKUP(B16,'비품현황표(전체)'!$A$1:$F$273,6,FALSE)) -> 고위험의약품 | H16: 3
... A22: 21 | B22: XNaK20 | C22: Normal saline 100ml+KCl 20mEq | D22: NaKCl (20meq/100ml) | E22: 20BTL/BOX | F22: 밀봉용기, 실온(1~30℃)보관 | G22: =IF(VLOOKUP(B22,'비품현황표(전체)'!$A$1:$F$273,6,FALSE)=0,"",VLOOKUP(B22,'비품현황표(전체)'!$A$1:$F$273,6,FALSE)) -> #N/A | H22: 3
A23: 22 | B23: XNITR10F | C23: Nitroglycerin 10mg | D23: Nitrolingual 10mg inj | E23: 10 AMP/BOX | F23: 밀봉용기, 실온보관 | G23: 유사모양 | H23: 3
A24: 23 | B24: XNORE10 | C24: Norepinephrine 10mg/10ml | D24: Norpin 10mg inj | E24: 10AMP/BOX | F24: 차광밀봉용기, 실온보관(1-30) | G24: =IF(VLOOKUP(B24,'비품현황표(전체)'!$A$1:$F$273,6,FALSE)=0,"",VLOOKUP(B24,'비품현황표(전체)'!$A$1:$F$273,6,FALSE)) | H24: 10
A25: 24 | B25: XPANTO4 | C25: Pantoprazole 40mg inj. | D25: Pantoline 40mg inj | E25: 1VIAL/BOX | F25: 차광밀봉용기, 25℃ 이하 | G25: =IF(VLOOKUP(B25,'비품현황표(전체)'!$A$1:$F$273,6,FALSE)=0,"",VLOOKUP(B25,'비품현황표(전체)'!$A$1:$F$273,6,FALSE)) | H25: 5
A26: 25 | B26: XCPENIR | C26: Chlorpheniramine | D26: Peniramin 4mg/2ml inj | E26: 100AMP/BOX | F26: 밀봉용기 | G26: =IF(VLOOKUP(B26,'비품현황표(전체)'!$A$1:$F$273,6,FALSE)=0,"",VLOOKUP(B26,'비품현황표(전체)'!$A$1:$F$273,6,FALSE)) | H26: 2
A27: 26 | B27: XHPD | C27: Haloperidol 5mg/1ml | D27: Peridol 5mg inj | E27: 10AMP/BOX | F27: 밀봉용기, 차광하여 실온보관 | G27: =IF(VLOOKUP(B27,'비품현황표(전체)'!$A$1:$F$273,6,FALSE)=0,"",VLOOKUP(B27,'비품현황표(전체)'!$A$1:$F$273,6,FALSE)) -> 유사발음 | H27: 2
A28: 27 | B28: XKPHMB | C28: Potassium phosphate monobasic 20ml inj | D28: Phosten 20ml inj | E28: 50AMP/BOX | F28: 밀봉용기, 15-30℃에서 보관 | G28: =IF(VLOOKUP(B28,'비품현황표(전체)'!$A$1:$F$273,6,FALSE)=0,"",VLOOKUP(B28,'비품현황표(전체)'!$A$1:$F$273,6,FALSE)) | H28: 5
A29: 28 | B29: XNB84 | C29: NaHCO3 8.4% 20ml amp | D29: Sod.bicarbonate 8.4% 20ml inj | E29: 50AMP/BOX | F29: 밀봉용기, 실온보관(1~30℃) | G29: =IF(VLOOKUP(B29,'비품현황표(전체)'!$A$1:$F$273,6,FALSE)=0,"",VLOOKUP(B29,'비품현황표(전체)'!$A$1:$F$273,6,FALSE)) | H29: 10
A30: 29 | B30: XTRANEX5 | D30: Tranexamic acid 500mg/5ml inj | F30: 밀봉용기, 실온(1～30℃)보관 | G30: =IF(VLOOKUP(B30,'비품현황표(전체)'!$A$1:$F$273,6,FALSE)=0,"",VLOOKUP(B30,'비품현황표(전체)'!$A$1:$F$273,6,FALSE)) | H30: 3
A31: 30 | B31: XTRAM50 | C31: Tramadol 50mg/ml | D31: Tridol 50mg inj | E31: 50AMP/BOX | F31: 밀봉용기, 실온(1～30℃)보관 | G31: =IF(VLOOKUP(B31,'비품현황표(전체)'!$A$1:$F$273,6,FALSE)=0,"",VLOOKUP(B31,'비품현황표(전체)'!$A$1:$F$273,6,FALSE)) | H31: 3
A32: 31 | B32: XDOPA4 | C32: Dopamine HCl 400mg | D32: Tropin 400mg inj | E32: 5AMP/BOX | F32: 차광한 밀봉용기 | G32: =IF(VLOOKUP(B32,'비품현황표(전체)'!$A$1:$F$273,6,FALSE)=0,"",VLOOKUP(B32,'비품현황표(전체)'!$A$1:$F$273,6,FALSE)) | H32: 6
A33: 32 | B33: XADH | C33: Vasopressin 20u | D33: Vasopressin 20u inj | E33: 10AMP/BOX | F33: 동결을 피하여 냉소보존(15℃이하), 밀봉용기 | G33: =IF(VLOOKUP(B33,'비품현황표(전체)'!$A$1:$F$273,6,FALSE)=0,"",VLOOKUP(B33,'비품현황표(전체)'!$A$1:$F$273,6,FALSE)) | H33: 5
D34: 보유비품약 품목수 | H34: 32

Sheet AN
A1: NO | B1: 약품코드 | C1: 일반명 | D1: 영문상품명 | E1: 규격 | F1: 보관조건 | G1: 혼돈주의약품 | H1: 26.06.17
A2: 1 | B2: XAPH1 | D2: Acetphen 1g/100ml premix inj | F2: 실온보관(1~30℃), 밀봉용기 | G2: =IF(VLOOKUP(B2,'비품현황표(전체)'!$A$1:$F$273,6,FALSE)=0,"",VLOOKUP(B2,'비품현황표(전체)'!$A$1:$F$273,6,FALSE)) | H2: 50
A3: 2 | B3: XNEFOP20 | D3: Acupan 20mg/2mL inj | F3: 밀봉용기, 실온(1～30℃)보관 | G3: =IF(VLOOKUP(B3,'비품현황표(전체)'!$A$1:$F$273,6,FALSE)=0,"",VLOOKUP(B3,'비품현황표(전체)'!$A$1:$F$273,6,FALSE)) | H3: 30
A4: 3 | B4: XADENO6 | C4: Adenosine 6mg | D4: Adenocor 6mg/2ml inj | E4: 6VIAL/BOX | F4: 밀봉용기 | G4: =IF(VLOOKUP(B4,'비품현황표(전체)'!$A$1:$F$273,6,FALSE)=0,"",VLOOKUP(B4,'비품현황표(전체)'!$A$1:$F$273,6,FALSE)) | H4: 4
A5: 4 | B5: XPALON75 | C5: Palonosetron 0.075mg/1.5ml | D5: Aloxi 0.075mg/1.5ml inj | E5: 5vial/BOX | F5: 실온(1∼30℃)보관, 밀봉용기, 차광보관 | G5: =IF(VLOOKUP(B5,'비품현황표(전체)'!$A$1:$F$273,6,FALSE)=0,"",VLOOKUP(B5,'비품현황표(전체)'!$A$1:$F$273,6,FALSE)) -> 용량고주의 | H5: 20
A6: 5 | B6: X20AL1S | C6: Albumin 20% 100ml(SK) | D6: Albumin(SK) 20% 100ml inj | F6: 밀봉용기, 30℃이하에서 동결을 피하여 보관 | G6: =IF(VLOOKUP(B6,'비품현황표(전체)'!$A$1:$F$273,6,FALSE)=0,"",VLOOKUP(B6,'비품현황표(전체)'!$A$1:$F$273,6,FALSE)) -> 용량고주의 | H6: 2
A7: 6 | B7: XATRO | C7: Atropine sulfate 0.5mg | D7: Atropine sulfate 0.5mg/1ml inj | E7: 50AMP/BOX | F7: 차광밀봉용기, 실온(1-30℃)보관 | G7: =IF(VLOOKUP(B7,'비품현황표(전체)'!$A$1:$F$273,6,FALSE)=0,"",VLOOKUP(B7,'비품현황표(전체)'!$A$1:$F$273,6,FALSE)) | H7: 44
A8: 7 | B8: IPRAT-RS | C8: Ipratropium bromide inh.soln 500mcg/2ml | D8: Atrovent UDV 2ml/Amp | E8: 20AMP/BOX*54 | F8: 밀봉용기, 실온보관 | G8: =IF(VLOOKUP(B8,'비품현황표(전체)'!$A$1:$F$273,6,FALSE)=0,"",VLOOKUP(B8,'비품현황표(전체)'!$A$1:$F$273,6,FALSE)) -> 유사모양 | H8: 2
A9: 8 | B9: XNICAR5 | D9: Binicapin 5mg/5ml inj | F9: 차광, 실온(1~30℃)보관 | G9: =IF(VLOOKUP(B9,'비품현황표(전체)'!$A$1:$F$273,6,FALSE)=0,"",VLOOKUP(B9,'비품현황표(전체)'!$A$1:$F$273,6,FALSE)) | H9: 20
A10: 9 | B10: XEMOL1 | C10: Esmolol HCl 100mg | D10: Brevibloc 100mg inj | E10: 20VIA/BOX | F10: 실온보관 | G10: =IF(VLOOKUP(B10,'비품현황표(전체)'!$A$1:$F$273,6,FALSE)=0,"",VLOOKUP(B10,'비품현황표(전체)'!$A$1:$F$273,6,FALSE)) | H10: 20
A11: 10 | B11: XCAGL | C11: Calcium gluconate 9.29mEq/amp | D11: Calcium gluconate 2g inj | E11: 50AMP/BOX | F11: 밀봉용기, 실온(1 - 30℃)보관 | G11: =IF(VLOOKUP(B11,'비품현황표(전체)'!$A$1:$F$273,6,FALSE)=0,"",VLOOKUP(B11,'비품현황표(전체)'!$A$1:$F$273,6,FALSE)) | H11: 10
A12: 11 | B12: XICARM | C12: Indigocarmine 0.8% | D12: Carmine 0.8% 5ml inj | E12: 10AMP/BOX | F12: 차광한 밀봉용기, 실온(1~30℃)보관 | G12: =IF(VLOOKUP(B12,'비품현황표(전체)'!$A$1:$F$273,6,FALSE)=0,"",VLOOKUP(B12,'비품현황표(전체)'!$A$1:$F$273,6,FALSE)) | H12: 5
A13: 12 | B13: XICGR25W | D13: Celbion green 25mg inj | F13: 차광밀봉용기, 실온(1~30℃)보관 | G13: =IF(VLOOKUP(B13,'비품현황표(전체)'!$A$1:$F$273,6,FALSE)=0,"",VLOOKUP(B13,'비품현황표(전체)'!$A$1:$F$273,6,FALSE)) | H13: 1
A14: 13 | B14: XAMIOD | C14: Amiodarone 150mg | D14: Cordarone 150mg/3ml inj | E14: 6AMP/BOX | F14: 밀봉용기 | G14: =IF(VLOOKUP(B14,'비품현황표(전체)'!$A$1:$F$273,6,FALSE)=0,"",VLOOKUP(B14,'비품현황표(전체)'!$A$1:$F$273,6,FALSE)) | H14: 8
A15: 14 | B15: XPCMOL | C15: Propacetamol 1g | D15: Denogan 1g inj | E15: 10VIA/BOX | F15: 차광밀봉용기, 1~25℃보관 | G15: =IF(VLOOKUP(B15,'비품현황표(전체)'!$A$1:$F$273,6,FALSE)=0,"",VLOOKUP(B15,'비품현황표(전체)'!$A$1:$F$273,6,FALSE)) | H15: 50
A16: 15 | B16: XDXM | C16: Dexamethasone 5mg | D16: Dexamethasone 5mg inj | E16: 50AMP/BOX | F16: 차광한 밀봉용기, 실온(1 ~ 30℃) 보관 | G16: =IF(VLOOKUP(B16,'비품현황표(전체)'!$A$1:$F$273,6,FALSE)=0,"",VLOOKUP(B16,'비품현황표(전체)'!$A$1:$F$273,6,FALSE)) -> 유사발음 | H16: 30
